<?xml version='1.0'?>
<sdf version='1.7'>
  <model name='tryd'>
    <!-- Prevent internal collisions between leg parts to avoid jitter -->
    <self_collide>false</self_collide>

    <!-- BASE -->
    <link name='base_footprint'>
      <pose>0 0 0 0 0 0</pose>
    </link>

    <joint name='base_joint' type='fixed'>
      <parent>base_footprint</parent>
      <child>base_link</child>
    </joint>

    <link name='base_link'>
      <pose>0 0 0 0 0 0</pose>
      <inertial>
        <pose>-8.94907244384436E-06 1.56777004396414E-08 -0.0099999786979822 0 0 0</pose>
        <mass>5.51387120943428</mass>
        <inertia>
          <ixx>0.0134468927294375</ixx>
          <ixy>-2.59140603594283E-08</ixy>
          <ixz>-3.51546984955843E-08</ixz>
          <iyy>0.165475287417608</iyy>
          <iyz>-1.62022466077164E-11</iyz>
          <izz>0.178554327537039</izz>
        </inertia>
      </inertial>
      <visual name='visual'>
        <geometry>
          <mesh>
            <uri>model://tryd/meshes/base_link.STL</uri>
          </mesh>
        </geometry>
        <material>
          <script>
            <name>Gazebo/White</name>
            <uri>file://media/materials/scripts/gazebo.material</uri>
          </script>
        </material>
      </visual>
      <collision name='collision'>
        <geometry>
          <mesh>
            <uri>model://tryd/meshes/base_link.STL</uri>
          </mesh>
        </geometry>
      </collision>
    </link>

    <!-- ========================================== -->
    <!-- RIGHT FRONT (RF) LEG -->
    <!-- ========================================== -->
    <joint name='j2_rf' type='revolute'>
      <pose relative_to='base_link'>0.239999999999999 -0.128 -0.0100000000000003 0 0 0</pose>
      <parent>base_link</parent>
      <child>l2_rf</child>
      <axis>
        <xyz>0 1 0</xyz>
        <limit>
          <lower>-50</lower>
          <upper>50</upper>
          <effort>100</effort>
          <velocity>50</velocity>
        </limit>
      </axis>
    </joint>

    <link name='l2_rf'>
      <pose relative_to='j2_rf'>0 0 0 0 0 0</pose>
      <inertial>
        <pose>-2.08804529222562E-10 -0.0291950635463956 2.32404020325735E-11 0 0 0</pose>
        <mass>0.196608556113688</mass>
        <inertia>
          <ixx>0.000799</ixx>
          <ixy>0.000000</ixy>
          <ixz>0.000000</ixz>
          <iyy>0.001288</iyy>
          <iyz>0.000000</iyz>
          <izz>0.000799</izz>
        </inertia>
      </inertial>
      <visual name='v'>
        <geometry>
          <mesh>
            <uri>model://tryd/meshes/l2_rf.STL</uri>
          </mesh>
        </geometry>
        <material>
          <script>
            <name>Gazebo/White</name>
            <uri>file://media/materials/scripts/gazebo.material</uri>
          </script>
        </material>
      </visual>
      <collision name='c'>
        <geometry>
          <mesh>
            <uri>model://tryd/meshes/l2_rf.STL</uri>
          </mesh>
        </geometry>
      </collision>
    </link>

    <joint name='j1_rf' type='revolute'>
      <pose relative_to='l2_rf'>0 -0.021 0 0 0 0</pose>
      <parent>l2_rf</parent>
      <child>l1_rf</child>
      <axis>
        <xyz>0 1 0</xyz>
        <limit>
          <lower>-1</lower>
          <upper>1</upper>
          <effort>100</effort>
          <velocity>50</velocity>
        </limit>
      </axis>
    </joint>

    <link name='l1_rf'>
      <pose relative_to='j1_rf'>0 0 0 0 0 0</pose>
      <inertial>
        <pose>-4.9960036108132E-16 -0.0161380765502627 -2.57744127660233E-16 0 0 0</pose>
        <mass>0.0354240975198173</mass>
        <inertia>
          <ixx>0.000012</ixx>
          <ixy>0.000000</ixy>
          <ixz>0.000000</ixz>
          <iyy>0.000015</iyy>
          <iyz>0.000000</iyz>
          <izz>0.000012</izz>
        </inertia>
      </inertial>
      <visual name='v'>
        <geometry>
          <mesh>
            <uri>model://tryd/meshes/l1_rf.STL</uri>
          </mesh>
        </geometry>
        <material>
          <script>
            <name>Gazebo/Grey</name>
            <uri>file://media/materials/scripts/gazebo.material</uri>
          </script>
        </material>
      </visual>
      <collision name='c'>
        <geometry>
          <mesh>
            <uri>model://tryd/meshes/l1_rf.STL</uri>
          </mesh>
        </geometry>
      </collision>
    </link>

    <!-- RF BRANCHES L3 -->
    <joint name='j3_rf1' type='revolute'>
      <pose relative_to='l1_rf'>0.022146669767068 0 0.0202367244935637 0 0 0</pose>
      <parent>l1_rf</parent>
      <child>l3_rf1</child>
      <axis>
        <xyz>0 1 0</xyz>
        <limit>
          <lower>-1.57</lower>
          <upper>1.57</upper>
          <effort>5</effort>
          <velocity>2</velocity>
        </limit>
      </axis>
    </joint>

    <link name='l3_rf1'>
      <pose relative_to='j3_rf1'>0 0 0 0 0 0</pose>
      <inertial>
        <pose>-0.0398905245666624 -0.0140000194157354 0.0482877588732501 0 0 0</pose>
        <mass>0.0557316685279916</mass>
        <inertia>
          <ixx>0.000029</ixx>
          <ixy>0.000000</ixy>
          <ixz>-0.000032</ixz>
          <iyy>0.000071</iyy>
          <iyz>0.000000</iyz>
          <izz>0.000044</izz>
        </inertia>
      </inertial>
      <visual name='v'>
        <geometry>
          <mesh>
            <uri>model://tryd/meshes/l3_rf1.STL</uri>
          </mesh>
        </geometry>
      </visual>
      <collision name='c'>
        <geometry>
          <mesh>
            <uri>model://tryd/meshes/l3_rf1.STL</uri>
          </mesh>
        </geometry>
      </collision>
    </link>

    <joint name='j3_rf2' type='revolute'>
      <pose relative_to='l1_rf'>-0.0285988523843481 0 0.00906121638072432 0 0 0</pose>
      <parent>l1_rf</parent>
      <child>l3_rf2</child>
      <axis>
        <xyz>0 1 0</xyz>
        <limit>
          <lower>-1.57</lower>
          <upper>1.57</upper>
          <effort>5</effort>
          <velocity>2</velocity>
        </limit>
      </axis>
    </joint>

    <link name='l3_rf2'>
      <pose relative_to='j3_rf2'>0 0 0 0 0 0</pose>
      <inertial>
        <pose>-0.0218731622438092 -0.0140000036638266 -0.0586901178612239 0 0 0</pose>
        <mass>0.0557315697331534</mass>
        <inertia>
          <ixx>0.000068</ixx>
          <ixy>0.000000</ixy>
          <ixz>0.000009</ixz>
          <iyy>0.000071</iyy>
          <iyz>0.000000</iyz>
          <izz>0.000006</izz>
        </inertia>
      </inertial>
      <visual name='v'>
        <geometry>
          <mesh>
            <uri>model://tryd/meshes/l3_rf2.STL</uri>
          </mesh>
        </geometry>
      </visual>
      <collision name='c'>
        <geometry>
          <mesh>
            <uri>model://tryd/meshes/l3_rf2.STL</uri>
          </mesh>
        </geometry>
      </collision>
    </link>

    <joint name='j3_rf3' type='revolute'>
      <pose relative_to='l1_rf'>0.00645218261727812 0 -0.0292979408742882 0 0 0</pose>
      <parent>l1_rf</parent>
      <child>l3_rf3</child>
      <axis>
        <xyz>0 1 0</xyz>
        <limit>
          <lower>-1.57</lower>
          <upper>1.57</upper>
          <effort>5</effort>
          <velocity>2</velocity>
        </limit>
      </axis>
    </joint>

    <link name='l3_rf3'>
      <pose relative_to='j3_rf3'>0 0 0 0 0 0</pose>
      <inertial>
        <pose>0.0617637116997839 -0.0140000031232566 0.0104023387554542 0 0 0</pose>
        <mass>0.0557315625814883</mass>
        <inertia>
          <ixx>0.000013</ixx>
          <ixy>0.000000</ixy>
          <ixz>0.000022</ixz>
          <iyy>0.000071</iyy>
          <iyz>0.000000</iyz>
          <izz>0.000061</izz>
        </inertia>
      </inertial>
      <visual name='v'>
        <geometry>
          <mesh>
            <uri>model://tryd/meshes/l3_rf3.STL</uri>
          </mesh>
        </geometry>
      </visual>
      <collision name='c'>
        <geometry>
          <mesh>
            <uri>model://tryd/meshes/l3_rf3.STL</uri>
          </mesh>
        </geometry>
      </collision>
    </link>

    <!-- RF BRANCHES L4 -->
    <joint name='j4_rf1' type='revolute'>
      <pose relative_to='l2_rf'>-0.0833137378878261 0 0.0687227842797317 0 0 0</pose>
      <parent>l2_rf</parent>
      <child>l4_rf1</child>
      <axis>
        <xyz>0 1 0</xyz>
        <limit>
          <lower>-1.57</lower>
          <upper>1.57</upper>
          <effort>5</effort>
          <velocity>2</velocity>
        </limit>
      </axis>
    </joint>

    <link name='l4_rf1'>
      <pose relative_to='j4_rf1'>0 0 0 0 0 0</pose>
      <inertial>
        <pose>-0.00925877524108323 -0.0350000059049338 -0.0714258099295615 0 0 0</pose>
        <mass>0.505772953738006</mass>
        <inertia>
          <ixx>0.001678</ixx>
          <ixy>0.000000</ixy>
          <ixz>-0.000035</ixz>
          <iyy>0.001703</iyy>
          <iyz>0.000000</iyz>
          <izz>0.000215</izz>
        </inertia>
      </inertial>
      <visual name='v'>
        <geometry>
          <mesh>
            <uri>model://tryd/meshes/l4_rf1.STL</uri>
          </mesh>
        </geometry>
      </visual>
      <collision name='c'>
        <geometry>
          <mesh>
            <uri>model://tryd/meshes/l4_rf1.STL</uri>
          </mesh>
        </geometry>
        <surface>
          <friction>
            <ode>
              <mu>0.6</mu>
              <mu2>0.6</mu2>
            </ode>
          </friction>
        </surface>
      </collision>
    </link>

    <joint name='j4_rf2' type='revolute'>
      <pose relative_to='l2_rf'>-0.0178588080611313 0 -0.106513205634962 0 0 0</pose>
      <parent>l2_rf</parent>
      <child>l4_rf2</child>
      <axis>
        <xyz>0 1 0</xyz>
        <limit>
          <lower>-1.57</lower>
          <upper>1.57</upper>
          <effort>5</effort>
          <velocity>2</velocity>
        </limit>
      </axis>
    </joint>

    <link name='l4_rf2'>
      <pose relative_to='j4_rf2'>0 0 0 0 0 0</pose>
      <inertial>
        <pose>0.0664859496958133 -0.0350000060684984 0.0276945733610566 0 0 0</pose>
        <mass>0.505772947420474</mass>
        <inertia>
          <ixx>0.000611</ixx>
          <ixy>0.000000</ixy>
          <ixz>0.000651</ixz>
          <iyy>0.001703</iyy>
          <iyz>0.000000</iyz>
          <izz>0.001282</izz>
        </inertia>
      </inertial>
      <visual name='v'>
        <geometry>
          <mesh>
            <uri>model://tryd/meshes/l4_rf2.STL</uri>
          </mesh>
        </geometry>
      </visual>
      <collision name='c'>
        <geometry>
          <mesh>
            <uri>model://tryd/meshes/l4_rf2.STL</uri>
          </mesh>
        </geometry>
        <surface>
          <friction>
            <ode>
              <mu>0.6</mu>
              <mu2>0.6</mu2>
            </ode>
          </friction>
        </surface>
      </collision>
    </link>

    <joint name='j4_rf3' type='revolute'>
      <pose relative_to='l2_rf'>0.101172545948959 0 0.0377904213552305 0 0 0</pose>
      <parent>l2_rf</parent>
      <child>l4_rf3</child>
      <axis>
        <xyz>0 1 0</xyz>
        <limit>
          <lower>-1.57</lower>
          <upper>1.57</upper>
          <effort>5</effort>
          <velocity>2</velocity>
        </limit>
      </axis>
    </joint>

    <link name='l4_rf3'>
      <pose relative_to='j4_rf3'>0 0 0 0 0 0</pose>
      <inertial>
        <pose>-0.0572271801527385 -0.0350000060490628 0.0437312355375022 0 0 0</pose>
        <mass>0.505772946196365</mass>
        <inertia>
          <ixx>0.000551</ixx>
          <ixy>0.000000</ixy>
          <ixz>-0.000616</ixz>
          <iyy>0.001703</iyy>
          <iyz>0.000000</iyz>
          <izz>0.001342</izz>
        </inertia>
      </inertial>
      <visual name='v'>
        <geometry>
          <mesh>
            <uri>model://tryd/meshes/l4_rf3.STL</uri>
          </mesh>
        </geometry>
      </visual>
      <collision name='c'>
        <geometry>
          <mesh>
            <uri>model://tryd/meshes/l4_rf3.STL</uri>
          </mesh>
        </geometry>
        <surface>
          <friction>
            <ode>
              <mu>0.6</mu>
              <mu2>0.6</mu2>
            </ode>
          </friction>
        </surface>
      </collision>
    </link>

    <!-- ========================================== -->
    <!-- LEFT FRONT (LF) LEG -->
    <!-- ========================================== -->
    <joint name='j2_lf' type='revolute'>
      <pose relative_to='base_link'>0.239999999999999 0.128 -0.0100000000000002 0 0 0</pose>
      <parent>base_link</parent>
      <child>l2_lf</child>
      <axis>
        <xyz>0 1 0</xyz>
        <limit>
          <lower>-50</lower>
          <upper>50</upper>
          <effort>100</effort>
          <velocity>50</velocity>
        </limit>
      </axis>
    </joint>

    <link name='l2_lf'>
      <pose relative_to='j2_lf'>0 0 0 0 0 0</pose>
      <inertial>
        <pose>-6.09346184621273E-11 0.0291950636027025 2.85822192691364E-10 0 0 0</pose>
        <mass>0.196608558229839</mass>
        <inertia>
          <ixx>0.000799</ixx>
          <ixy>0.000000</ixy>
          <ixz>0.000000</ixz>
          <iyy>0.001288</iyy>
          <iyz>0.000000</iyz>
          <izz>0.000799</izz>
        </inertia>
      </inertial>
      <visual name='v'>
        <geometry>
          <mesh>
            <uri>model://tryd/meshes/l2_lf.STL</uri>
          </mesh>
        </geometry>
        <material>
          <script>
            <name>Gazebo/White</name>
            <uri>file://media/materials/scripts/gazebo.material</uri>
          </script>
        </material>
      </visual>
      <collision name='c'>
        <geometry>
          <mesh>
            <uri>model://tryd/meshes/l2_lf.STL</uri>
          </mesh>
        </geometry>
      </collision>
    </link>

    <joint name='j1_lf' type='revolute'>
      <pose relative_to='l2_lf'>0 0.021 0 0 0 0</pose>
      <parent>l2_lf</parent>
      <child>l1_lf</child>
      <axis>
        <xyz>0 1 0</xyz>
        <limit>
          <lower>-1</lower>
          <upper>1</upper>
          <effort>100</effort>
          <velocity>50</velocity>
        </limit>
      </axis>
    </joint>

    <link name='l1_lf'>
      <pose relative_to='j1_lf'>0 0 0 0 0 0</pose>
      <inertial>
        <pose>-2.22044604925031E-16 0.0161380765502627 -4.56316275036442E-16 0 0 0</pose>
        <mass>0.0354240975198172</mass>
        <inertia>
          <ixx>0.000012</ixx>
          <ixy>0.000000</ixy>
          <ixz>0.000000</ixz>
          <iyy>0.000015</iyy>
          <iyz>0.000000</iyz>
          <izz>0.000012</izz>
        </inertia>
      </inertial>
      <visual name='v'>
        <geometry>
          <mesh>
            <uri>model://tryd/meshes/l1_lf.STL</uri>
          </mesh>
        </geometry>
      </visual>
      <collision name='c'>
        <geometry>
          <mesh>
            <uri>model://tryd/meshes/l1_lf.STL</uri>
          </mesh>
        </geometry>
      </collision>
    </link>

    <!-- LF BRANCHES L3 -->
    <joint name='j3_lf1' type='revolute'>
      <pose relative_to='l1_lf'>0.0221395963706941 0 0.0202444627625115 0 0 0</pose>
      <parent>l1_lf</parent>
      <child>l3_lf1</child>
      <axis>
        <xyz>0 1 0</xyz>
        <limit>
          <lower>-1.57</lower>
          <upper>1.57</upper>
          <effort>5</effort>
          <velocity>2</velocity>
        </limit>
      </axis>
    </joint>

    <link name='l3_lf1'>
      <pose relative_to='j3_lf1'>0 0 0 0 0 0</pose>
      <inertial>
        <pose>-0.039890520885456 0.0139999805842647 0.0482877619143034 0 0 0</pose>
        <mass>0.0557316685279918</mass>
        <inertia>
          <ixx>0.000029</ixx>
          <ixy>0.000000</ixy>
          <ixz>-0.000032</ixz>
          <iyy>0.000071</iyy>
          <iyz>0.000000</iyz>
          <izz>0.000044</izz>
        </inertia>
      </inertial>
      <visual name='v'>
        <geometry>
          <mesh>
            <uri>model://tryd/meshes/l3_lf1.STL</uri>
          </mesh>
        </geometry>
      </visual>
      <collision name='c'>
        <geometry>
          <mesh>
            <uri>model://tryd/meshes/l3_lf1.STL</uri>
          </mesh>
        </geometry>
      </collision>
    </link>

    <joint name='j3_lf2' type='revolute'>
      <pose relative_to='l1_lf'>-0.0286020172236509 0 0.00905122150529837 0 0 0</pose>
      <parent>l1_lf</parent>
      <child>l3_lf2</child>
      <axis>
        <xyz>0 1 0</xyz>
        <limit>
          <lower>-1.57</lower>
          <upper>1.57</upper>
          <effort>5</effort>
          <velocity>2</velocity>
        </limit>
      </axis>
    </joint>

    <link name='l3_lf2'>
      <pose relative_to='j3_lf2'>0 0 0 0 0 0</pose>
      <inertial>
        <pose>-0.0218731667180357 0.0139999963361724 -0.0586901161937509 0 0 0</pose>
        <mass>0.0557315697331413</mass>
        <inertia>
          <ixx>0.000068</ixx>
          <ixy>0.000000</ixy>
          <ixz>0.000009</ixz>
          <iyy>0.000071</iyy>
          <iyz>0.000000</iyz>
          <izz>0.000006</izz>
        </inertia>
      </inertial>
      <visual name='v'>
        <geometry>
          <mesh>
            <uri>model://tryd/meshes/l3_lf2.STL</uri>
          </mesh>
        </geometry>
      </visual>
      <collision name='c'>
        <geometry>
          <mesh>
            <uri>model://tryd/meshes/l3_lf2.STL</uri>
          </mesh>
        </geometry>
      </collision>
    </link>

    <joint name='j3_lf3' type='revolute'>
      <pose relative_to='l1_lf'>0.00646242085295634 0 -0.0292956842678118 0 0 0</pose>
      <parent>l1_lf</parent>
      <child>l3_lf3</child>
      <axis>
        <xyz>0 1 0</xyz>
        <limit>
          <lower>-1.57</lower>
          <upper>1.57</upper>
          <effort>5</effort>
          <velocity>2</velocity>
        </limit>
      </axis>
    </joint>

    <link name='l3_lf3'>
      <pose relative_to='j3_lf3'>0 0 0 0 0 0</pose>
      <inertial>
        <pose>0.0617637124928111 0.0139999968767433 0.0104023340469134 0 0 0</pose>
        <mass>0.0557315625814885</mass>
        <inertia>
          <ixx>0.000013</ixx>
          <ixy>0.000000</ixy>
          <ixz>0.000022</ixz>
          <iyy>0.000071</iyy>
          <iyz>0.000000</iyz>
          <izz>0.000061</izz>
        </inertia>
      </inertial>
      <visual name='v'>
        <geometry>
          <mesh>
            <uri>model://tryd/meshes/l3_lf3.STL</uri>
          </mesh>
        </geometry>
      </visual>
      <collision name='c'>
        <geometry>
          <mesh>
            <uri>model://tryd/meshes/l3_lf3.STL</uri>
          </mesh>
        </geometry>
      </collision>
    </link>

    <!-- LF BRANCHES L4 -->
    <joint name='j4_lf1' type='revolute'>
      <pose relative_to='l2_lf'>-0.0833137378878259 0 0.068722784279732 0 0 0</pose>
      <parent>l2_lf</parent>
      <child>l4_lf1</child>
      <axis>
        <xyz>0 1 0</xyz>
        <limit>
          <lower>-1.57</lower>
          <upper>1.57</upper>
          <effort>5</effort>
          <velocity>2</velocity>
        </limit>
      </axis>
    </joint>

    <link name='l4_lf1'>
      <pose relative_to='j4_lf1'>0 0 0 0 0 0</pose>
      <inertial>
        <pose>-0.00923381104475832 0.034999994095162 -0.0714290415484533 0 0 0</pose>
        <mass>0.505772953745336</mass>
        <inertia>
          <ixx>0.001678</ixx>
          <ixy>0.000000</ixy>
          <ixz>-0.000035</ixz>
          <iyy>0.001703</iyy>
          <iyz>0.000000</iyz>
          <izz>0.000215</izz>
        </inertia>
      </inertial>
      <visual name='v'>
        <geometry>
          <mesh>
            <uri>model://tryd/meshes/l4_lf1.STL</uri>
          </mesh>
        </geometry>
      </visual>
      <collision name='c'>
        <geometry>
          <mesh>
            <uri>model://tryd/meshes/l4_lf1.STL</uri>
          </mesh>
        </geometry>
        <surface>
          <friction>
            <ode>
              <mu>0.6</mu>
              <mu2>0.6</mu2>
            </ode>
          </friction>
        </surface>
      </collision>
    </link>

    <joint name='j4_lf2' type='revolute'>
      <pose relative_to='l2_lf'>-0.0178588080611317 0 -0.106513205634961 0 0 0</pose>
      <parent>l2_lf</parent>
      <child>l4_lf2</child>
      <axis>
        <xyz>0 1 0</xyz>
        <limit>
          <lower>-1.57</lower>
          <upper>1.57</upper>
          <effort>5</effort>
          <velocity>2</velocity>
        </limit>
      </axis>
    </joint>

    <link name='l4_lf2'>
      <pose relative_to='j4_lf2'>0 0 0 0 0 0</pose>
      <inertial>
        <pose>0.0664762662590837 0.0349999939314377 0.0277178088028784 0 0 0</pose>
        <mass>0.505772947416741</mass>
        <inertia>
          <ixx>0.000611</ixx>
          <ixy>0.000000</ixy>
          <ixz>0.000651</ixz>
          <iyy>0.001703</iyy>
          <iyz>0.000000</iyz>
          <izz>0.001282</izz>
        </inertia>
      </inertial>
      <visual name='v'>
        <geometry>
          <mesh>
            <uri>model://tryd/meshes/l4_lf2.STL</uri>
          </mesh>
        </geometry>
      </visual>
      <collision name='c'>
        <geometry>
          <mesh>
            <uri>model://tryd/meshes/l4_lf2.STL</uri>
          </mesh>
        </geometry>
        <surface>
          <friction>
            <ode>
              <mu>0.6</mu>
              <mu2>0.6</mu2>
            </ode>
          </friction>
        </surface>
      </collision>
    </link>

    <joint name='j4_lf3' type='revolute'>
      <pose relative_to='l2_lf'>0.101172545948959 0 0.0377904213552303 0 0 0</pose>
      <parent>l2_lf</parent>
      <child>l4_lf3</child>
      <axis>
        <xyz>0 1 0</xyz>
        <limit>
          <lower>-1.57</lower>
          <upper>1.57</upper>
          <effort>5</effort>
          <velocity>2</velocity>
        </limit>
      </axis>
    </joint>

    <link name='l4_lf3'>
      <pose relative_to='j4_lf3'>0 0 0 0 0 0</pose>
      <inertial>
        <pose>-0.0572424609164388 0.0349999939510116 0.0437112317178428 0 0 0</pose>
        <mass>0.505772946198787</mass>
        <inertia>
          <ixx>0.000551</ixx>
          <ixy>0.000000</ixy>
          <ixz>-0.000616</ixz>
          <iyy>0.001703</iyy>
          <iyz>0.000000</iyz>
          <izz>0.001342</izz>
        </inertia>
      </inertial>
      <visual name='v'>
        <geometry>
          <mesh>
            <uri>model://tryd/meshes/l4_lf3.STL</uri>
          </mesh>
        </geometry>
      </visual>
      <collision name='c'>
        <geometry>
          <mesh>
            <uri>model://tryd/meshes/l4_lf3.STL</uri>
          </mesh>
        </geometry>
        <surface>
          <friction>
            <ode>
              <mu>0.6</mu>
              <mu2>0.6</mu2>
            </ode>
          </friction>
        </surface>
      </collision>
    </link>

    <!-- ========================================== -->
    <!-- RIGHT HIND (RH) LEG -->
    <!-- ========================================== -->
    <joint name='j2_rh' type='revolute'>
      <pose relative_to='base_link'>-0.24 -0.128 -0.0100000000000005 0 0 0</pose>
      <parent>base_link</parent>
      <child>l2_rh</child>
      <axis>
        <xyz>0 1 0</xyz>
        <limit>
          <lower>-50</lower>
          <upper>50</upper>
          <effort>100</effort>
          <velocity>50</velocity>
        </limit>
      </axis>
    </joint>

    <link name='l2_rh'>
      <pose relative_to='j2_rh'>0 0 0 0 0 0</pose>
      <inertial>
        <pose>-3.36830535685451E-10 -0.0291950635763487 4.28708644196799E-11 0 0 0</pose>
        <mass>0.196608557895127</mass>
        <inertia>
          <ixx>0.000799</ixx>
          <ixy>0.000000</ixy>
          <ixz>0.000000</ixz>
          <iyy>0.001288</iyy>
          <iyz>0.000000</iyz>
          <izz>0.000799</izz>
        </inertia>
      </inertial>
      <visual name='v'>
        <geometry>
          <mesh>
            <uri>model://tryd/meshes/l2_rh.STL</uri>
          </mesh>
        </geometry>
        <material>
          <script>
            <name>Gazebo/White</name>
            <uri>file://media/materials/scripts/gazebo.material</uri>
          </script>
        </material>
      </visual>
      <collision name='c'>
        <geometry>
          <mesh>
            <uri>model://tryd/meshes/l2_rh.STL</uri>
          </mesh>
        </geometry>
      </collision>
    </link>

    <joint name='j1_rh' type='revolute'>
      <pose relative_to='l2_rh'>0 -0.021 0 0 0 0</pose>
      <parent>l2_rh</parent>
      <child>l1_rh</child>
      <axis>
        <xyz>0 1 0</xyz>
        <limit>
          <lower>-1</lower>
          <upper>1</upper>
          <effort>100</effort>
          <velocity>50</velocity>
        </limit>
      </axis>
    </joint>

    <link name='l1_rh'>
      <pose relative_to='j1_rh'>0 0 0 0 0 0</pose>
      <inertial>
        <pose>3.33066907387547E-16 -0.0161380765502627 -2.59802701229211E-16 0 0 0</pose>
        <mass>0.0354240975198172</mass>
        <inertia>
          <ixx>0.000012</ixx>
          <ixy>0.000000</ixy>
          <ixz>0.000000</ixz>
          <iyy>0.000015</iyy>
          <iyz>0.000000</iyz>
          <izz>0.000012</izz>
        </inertia>
      </inertial>
      <visual name='v'>
        <geometry>
          <mesh>
            <uri>model://tryd/meshes/l1_rh.STL</uri>
          </mesh>
        </geometry>
      </visual>
      <collision name='c'>
        <geometry>
          <mesh>
            <uri>model://tryd/meshes/l1_rh.STL</uri>
          </mesh>
        </geometry>
      </collision>
    </link>

    <!-- RH BRANCHES L3 -->
    <joint name='j3_rh1' type='revolute'>
      <pose relative_to='l1_rh'>0.0221466697670692 0 0.0202367244935632 0 0 0</pose>
      <parent>l1_rh</parent>
      <child>l3_rh1</child>
      <axis>
        <xyz>0 1 0</xyz>
        <limit>
          <lower>-1.57</lower>
          <upper>1.57</upper>
          <effort>5</effort>
          <velocity>2</velocity>
        </limit>
      </axis>
    </joint>

    <link name='l3_rh1'>
      <pose relative_to='j3_rh1'>0 0 0 0 0 0</pose>
      <inertial>
        <pose>-0.0398905245666619 -0.0140000194157354 0.0482877588732504 0 0 0</pose>
        <mass>0.0557316685279918</mass>
        <inertia>
          <ixx>0.000029</ixx>
          <ixy>0.000000</ixy>
          <ixz>-0.000032</ixz>
          <iyy>0.000071</iyy>
          <iyz>0.000000</iyz>
          <izz>0.000044</izz>
        </inertia>
      </inertial>
      <visual name='v'>
        <geometry>
          <mesh>
            <uri>model://tryd/meshes/l3_rh1.STL</uri>
          </mesh>
        </geometry>
      </visual>
      <collision name='c'>
        <geometry>
          <mesh>
            <uri>model://tryd/meshes/l3_rh1.STL</uri>
          </mesh>
        </geometry>
      </collision>
    </link>

    <joint name='j3_rh2' type='revolute'>
      <pose relative_to='l1_rh'>-0.0285988523843469 0 0.00906121638072405 0 0 0</pose>
      <parent>l1_rh</parent>
      <child>l3_rh2</child>
      <axis>
        <xyz>0 1 0</xyz>
        <limit>
          <lower>-1.57</lower>
          <upper>1.57</upper>
          <effort>5</effort>
          <velocity>2</velocity>
        </limit>
      </axis>
    </joint>

    <link name='l3_rh2'>
      <pose relative_to='j3_rh2'>0 0 0 0 0 0</pose>
      <inertial>
        <pose>-0.0218731622438033 -0.0140000036638276 -0.0586901178612386 0 0 0</pose>
        <mass>0.0557315697331424</mass>
        <inertia>
          <ixx>0.000068</ixx>
          <ixy>0.000000</ixy>
          <ixz>0.000009</ixz>
          <iyy>0.000071</iyy>
          <iyz>0.000000</iyz>
          <izz>0.000006</izz>
        </inertia>
      </inertial>
      <visual name='v'>
        <geometry>
          <mesh>
            <uri>model://tryd/meshes/l3_rh2.STL</uri>
          </mesh>
        </geometry>
      </visual>
      <collision name='c'>
        <geometry>
          <mesh>
            <uri>model://tryd/meshes/l3_rh2.STL</uri>
          </mesh>
        </geometry>
      </collision>
    </link>

    <joint name='j3_rh3' type='revolute'>
      <pose relative_to='l1_rh'>0.00645218261727887 0 -0.0292979408742888 0 0 0</pose>
      <parent>l1_rh</parent>
      <child>l3_rh3</child>
      <axis>
        <xyz>0 1 0</xyz>
        <limit>
          <lower>-1.57</lower>
          <upper>1.57</upper>
          <effort>5</effort>
          <velocity>2</velocity>
        </limit>
      </axis>
    </joint>

    <link name='l3_rh3'>
      <pose relative_to='j3_rh3'>0 0 0 0 0 0</pose>
      <inertial>
        <pose>0.0617637116997811 -0.0140000031232566 0.0104023387554438 0 0 0</pose>
        <mass>0.0557315625814886</mass>
        <inertia>
          <ixx>0.000013</ixx>
          <ixy>0.000000</ixy>
          <ixz>0.000022</ixz>
          <iyy>0.000071</iyy>
          <iyz>0.000000</iyz>
          <izz>0.000061</izz>
        </inertia>
      </inertial>
      <visual name='v'>
        <geometry>
          <mesh>
            <uri>model://tryd/meshes/l3_rh3.STL</uri>
          </mesh>
        </geometry>
      </visual>
      <collision name='c'>
        <geometry>
          <mesh>
            <uri>model://tryd/meshes/l3_rh3.STL</uri>
          </mesh>
        </geometry>
      </collision>
    </link>

    <!-- RH BRANCHES L4 -->
    <joint name='j4_rh1' type='revolute'>
      <pose relative_to='l2_rh'>-0.0833137378878267 0 0.0687227842797326 0 0 0</pose>
      <parent>l2_rh</parent>
      <child>l4_rh1</child>
      <axis>
        <xyz>0 1 0</xyz>
        <limit>
          <lower>-1.57</lower>
          <upper>1.57</upper>
          <effort>5</effort>
          <velocity>2</velocity>
        </limit>
      </axis>
    </joint>

    <link name='l4_rh1'>
      <pose relative_to='j4_rh1'>0 0 0 0 0 0</pose>
      <inertial>
        <pose>-0.00925877524108371 -0.0350000059049338 -0.0714258099295591 0 0 0</pose>
        <mass>0.505772953738004</mass>
        <inertia>
          <ixx>0.001678</ixx>
          <ixy>0.000000</ixy>
          <ixz>-0.000035</ixz>
          <iyy>0.001703</iyy>
          <iyz>0.000000</iyz>
          <izz>0.000215</izz>
        </inertia>
      </inertial>
      <visual name='v'>
        <geometry>
          <mesh>
            <uri>model://tryd/meshes/l4_rh1.STL</uri>
          </mesh>
        </geometry>
      </visual>
      <collision name='c'>
        <geometry>
          <mesh>
            <uri>model://tryd/meshes/l4_rh1.STL</uri>
          </mesh>
        </geometry>
        <surface>
          <friction>
            <ode>
              <mu>0.6</mu>
              <mu2>0.6</mu2>
            </ode>
          </friction>
        </surface>
      </collision>
    </link>

    <joint name='j4_rh2' type='revolute'>
      <pose relative_to='l2_rh'>-0.0178588080611333 0 -0.106513205634961 0 0 0</pose>
      <parent>l2_rh</parent>
      <child>l4_rh2</child>
      <axis>
        <xyz>0 1 0</xyz>
        <limit>
          <lower>-1.57</lower>
          <upper>1.57</upper>
          <effort>5</effort>
          <velocity>2</velocity>
        </limit>
      </axis>
    </joint>

    <link name='l4_rh2'>
      <pose relative_to='j4_rh2'>0 0 0 0 0 0</pose>
      <inertial>
        <pose>0.0664859496958403 -0.0350000060684984 0.0276945733610724 0 0 0</pose>
        <mass>0.505772947420472</mass>
        <inertia>
          <ixx>0.000611</ixx>
          <ixy>0.000000</ixy>
          <ixz>0.000651</ixz>
          <iyy>0.001703</iyy>
          <iyz>0.000000</iyz>
          <izz>0.001282</izz>
        </inertia>
      </inertial>
      <visual name='v'>
        <geometry>
          <mesh>
            <uri>model://tryd/meshes/l4_rh2.STL</uri>
          </mesh>
        </geometry>
      </visual>
      <collision name='c'>
        <geometry>
          <mesh>
            <uri>model://tryd/meshes/l4_rh2.STL</uri>
          </mesh>
        </geometry>
        <surface>
          <friction>
            <ode>
              <mu>0.6</mu>
              <mu2>0.6</mu2>
            </ode>
          </friction>
        </surface>
      </collision>
    </link>

    <joint name='j4_rh3' type='revolute'>
      <pose relative_to='l2_rh'>0.101172545948958 0 0.03779042135523 0 0 0</pose>
      <parent>l2_rh</parent>
      <child>l4_rh3</child>
      <axis>
        <xyz>0 1 0</xyz>
        <limit>
          <lower>-1.57</lower>
          <upper>1.57</upper>
          <effort>5</effort>
          <velocity>2</velocity>
        </limit>
      </axis>
    </joint>

    <link name='l4_rh3'>
      <pose relative_to='j4_rh3'>0 0 0 0 0 0</pose>
      <inertial>
        <pose>-0.0572271801527114 -0.0350000060490628 0.0437312355374892 0 0 0</pose>
        <mass>0.505772946196363</mass>
        <inertia>
          <ixx>0.000551</ixx>
          <ixy>0.000000</ixy>
          <ixz>-0.000616</ixz>
          <iyy>0.001703</iyy>
          <iyz>0.000000</iyz>
          <izz>0.001342</izz>
        </inertia>
      </inertial>
      <visual name='v'>
        <geometry>
          <mesh>
            <uri>model://tryd/meshes/l4_rh3.STL</uri>
          </mesh>
        </geometry>
      </visual>
      <collision name='c'>
        <geometry>
          <mesh>
            <uri>model://tryd/meshes/l4_rh3.STL</uri>
          </mesh>
        </geometry>
        <surface>
          <friction>
            <ode>
              <mu>0.6</mu>
              <mu2>0.6</mu2>
            </ode>
          </friction>
        </surface>
      </collision>
    </link>

    <!-- ========================================== -->
    <!-- LEFT HIND (LH) LEG -->
    <!-- ========================================== -->
    <joint name='j2_lh' type='revolute'>
      <pose relative_to='base_link'>-0.239999999999999 0.128 -0.0100000000000004 0 0 0</pose>
      <parent>base_link</parent>
      <child>l2_lh</child>
      <axis>
        <xyz>0 1 0</xyz>
        <limit>
          <lower>-50</lower>
          <upper>50</upper>
          <effort>100</effort>
          <velocity>50</velocity>
        </limit>
      </axis>
    </joint>

    <link name='l2_lh'>
      <pose relative_to='j2_lh'>0 0 0 0 0 0</pose>
      <inertial>
        <pose>-6.25409724008819E-11 0.0291950635841788 3.76880211515852E-10 0 0 0</pose>
        <mass>0.196608558024231</mass>
        <inertia>
          <ixx>0.000799</ixx>
          <ixy>0.000000</ixy>
          <ixz>0.000000</ixz>
          <iyy>0.001288</iyy>
          <iyz>0.000000</iyz>
          <izz>0.000799</izz>
        </inertia>
      </inertial>
      <visual name='v'>
        <geometry>
          <mesh>
            <uri>model://tryd/meshes/l2_lh.STL</uri>
          </mesh>
        </geometry>
        <material>
          <script>
            <name>Gazebo/White</name>
            <uri>file://media/materials/scripts/gazebo.material</uri>
          </script>
        </material>
      </visual>
      <collision name='c'>
        <geometry>
          <mesh>
            <uri>model://tryd/meshes/l2_lh.STL</uri>
          </mesh>
        </geometry>
      </collision>
    </link>

    <joint name='j1_lh' type='revolute'>
      <pose relative_to='l2_lh'>0 0.021 0 0 0 0</pose>
      <parent>l2_lh</parent>
      <child>l1_lh</child>
      <axis>
        <xyz>0 1 0</xyz>
        <limit>
          <lower>-1</lower>
          <upper>1</upper>
          <effort>100</effort>
          <velocity>50</velocity>
        </limit>
      </axis>
    </joint>

    <link name='l1_lh'>
      <pose relative_to='j1_lh'>0 0 0 0 0 0</pose>
      <inertial>
        <pose>4.44089209850063E-16 0.0161380765502627 -4.43160424709541E-17 0 0 0</pose>
        <mass>0.0354240975198174</mass>
        <inertia>
          <ixx>0.000012</ixx>
          <ixy>0.000000</ixy>
          <ixz>0.000000</ixz>
          <iyy>0.000015</iyy>
          <iyz>0.000000</iyz>
          <izz>0.000012</izz>
        </inertia>
      </inertial>
      <visual name='v'>
        <geometry>
          <mesh>
            <uri>model://tryd/meshes/l1_lh.STL</uri>
          </mesh>
        </geometry>
      </visual>
      <collision name='c'>
        <geometry>
          <mesh>
            <uri>model://tryd/meshes/l1_lh.STL</uri>
          </mesh>
        </geometry>
      </collision>
    </link>

    <!-- LH BRANCHES L3 -->
    <joint name='j3_lh1' type='revolute'>
      <pose relative_to='l1_lh'>0.0221395963706951 0 0.0202444627625122 0 0 0</pose>
      <parent>l1_lh</parent>
      <child>l3_lh1</child>
      <axis>
        <xyz>0 1 0</xyz>
        <limit>
          <lower>-1.57</lower>
          <upper>1.57</upper>
          <effort>5</effort>
          <velocity>2</velocity>
        </limit>
      </axis>
    </joint>

    <link name='l3_lh1'>
      <pose relative_to='j3_lh1'>0 0 0 0 0 0</pose>
      <inertial>
        <pose>-0.0398905208854606 0.0139999805842646 0.0482877619143024 0 0 0</pose>
        <mass>0.0557316685279916</mass>
        <inertia>
          <ixx>0.000029</ixx>
          <ixy>0.000000</ixy>
          <ixz>-0.000032</ixz>
          <iyy>0.000071</iyy>
          <iyz>0.000000</iyz>
          <izz>0.000044</izz>
        </inertia>
      </inertial>
      <visual name='v'>
        <geometry>
          <mesh>
            <uri>model://tryd/meshes/l3_lh1.STL</uri>
          </mesh>
        </geometry>
      </visual>
      <collision name='c'>
        <geometry>
          <mesh>
            <uri>model://tryd/meshes/l3_lh1.STL</uri>
          </mesh>
        </geometry>
      </collision>
    </link>

    <joint name='j3_lh2' type='revolute'>
      <pose relative_to='l1_lh'>-0.02860201722365 0 0.00905122150529934 0 0 0</pose>
      <parent>l1_lh</parent>
      <child>l3_lh2</child>
      <axis>
        <xyz>0 1 0</xyz>
        <limit>
          <lower>-1.57</lower>
          <upper>1.57</upper>
          <effort>5</effort>
          <velocity>2</velocity>
        </limit>
      </axis>
    </joint>

    <link name='l3_lh2'>
      <pose relative_to='j3_lh2'>0 0 0 0 0 0</pose>
      <inertial>
        <pose>-0.0218731667180396 0.0139999963361724 -0.0586901161937471 0 0 0</pose>
        <mass>0.0557315697331413</mass>
        <inertia>
          <ixx>0.000068</ixx>
          <ixy>0.000000</ixy>
          <ixz>0.000009</ixz>
          <iyy>0.000071</iyy>
          <iyz>0.000000</iyz>
          <izz>0.000006</izz>
        </inertia>
      </inertial>
      <visual name='v'>
        <geometry>
          <mesh>
            <uri>model://tryd/meshes/l3_lh2.STL</uri>
          </mesh>
        </geometry>
      </visual>
      <collision name='c'>
        <geometry>
          <mesh>
            <uri>model://tryd/meshes/l3_lh2.STL</uri>
          </mesh>
        </geometry>
      </collision>
    </link>

    <joint name='j3_lh3' type='revolute'>
      <pose relative_to='l1_lh'>0.00646242085295679 0 -0.0292956842678109 0 0 0</pose>
      <parent>l1_lh</parent>
      <child>l3_lh3</child>
      <axis>
        <xyz>0 1 0</xyz>
        <limit>
          <lower>-1.57</lower>
          <upper>1.57</upper>
          <effort>5</effort>
          <velocity>2</velocity>
        </limit>
      </axis>
    </joint>

    <link name='l3_lh3'>
      <pose relative_to='j3_lh3'>0 0 0 0 0 0</pose>
      <inertial>
        <pose>0.0617637124928112 0.0139999968767434 0.0104023340469128 0 0 0</pose>
        <mass>0.0557315625814885</mass>
        <inertia>
          <ixx>0.000013</ixx>
          <ixy>0.000000</ixy>
          <ixz>0.000022</ixz>
          <iyy>0.000071</iyy>
          <iyz>0.000000</iyz>
          <izz>0.000061</izz>
        </inertia>
      </inertial>
      <visual name='v'>
        <geometry>
          <mesh>
            <uri>model://tryd/meshes/l3_lh3.STL</uri>
          </mesh>
        </geometry>
      </visual>
      <collision name='c'>
        <geometry>
          <mesh>
            <uri>model://tryd/meshes/l3_lh3.STL</uri>
          </mesh>
        </geometry>
      </collision>
    </link>

    <!-- LH BRANCHES L4 -->
    <joint name='j4_lh1' type='revolute'>
      <pose relative_to='l2_lh'>-0.0833137378878265 0 0.0687227842797328 0 0 0</pose>
      <parent>l2_lh</parent>
      <child>l4_lh1</child>
      <axis>
        <xyz>0 1 0</xyz>
        <limit>
          <lower>-1.57</lower>
          <upper>1.57</upper>
          <effort>5</effort>
          <velocity>2</velocity>
        </limit>
      </axis>
    </joint>

    <link name='l4_lh1'>
      <pose relative_to='j4_lh1'>0 0 0 0 0 0</pose>
      <inertial>
        <pose>-0.00923381104475846 0.0349999940951619 -0.0714290415484631 0 0 0</pose>
        <mass>0.505772953745337</mass>
        <inertia>
          <ixx>0.001678</ixx>
          <ixy>0.000000</ixy>
          <ixz>-0.000035</ixz>
          <iyy>0.001703</iyy>
          <iyz>0.000000</iyz>
          <izz>0.000215</izz>
        </inertia>
      </inertial>
      <visual name='v'>
        <geometry>
          <mesh>
            <uri>model://tryd/meshes/l4_lh1.STL</uri>
          </mesh>
        </geometry>
      </visual>
      <collision name='c'>
        <geometry>
          <mesh>
            <uri>model://tryd/meshes/l4_lh1.STL</uri>
          </mesh>
        </geometry>
        <surface>
          <friction>
            <ode>
              <mu>0.6</mu>
              <mu2>0.6</mu2>
            </ode>
          </friction>
        </surface>
      </collision>
    </link>

    <joint name='j4_lh2' type='revolute'>
      <pose relative_to='l2_lh'>-0.0178588080611337 0 -0.106513205634961 0 0 0</pose>
      <parent>l2_lh</parent>
      <child>l4_lh2</child>
      <axis>
        <xyz>0 1 0</xyz>
        <limit>
          <lower>-1.57</lower>
          <upper>1.57</upper>
          <effort>5</effort>
          <velocity>2</velocity>
        </limit>
      </axis>
    </joint>

    <link name='l4_lh2'>
      <pose relative_to='j4_lh2'>0 0 0 0 0 0</pose>
      <inertial>
        <pose>0.0664762662590742 0.0349999939314377 0.0277178088028722 0 0 0</pose>
        <mass>0.50577294741674</mass>
        <inertia>
          <ixx>0.000611</ixx>
          <ixy>0.000000</ixy>
          <ixz>0.000651</ixz>
          <iyy>0.001703</iyy>
          <iyz>0.000000</iyz>
          <izz>0.001282</izz>
        </inertia>
      </inertial>
      <visual name='v'>
        <geometry>
          <mesh>
            <uri>model://tryd/meshes/l4_lh2.STL</uri>
          </mesh>
        </geometry>
      </visual>
      <collision name='c'>
        <geometry>
          <mesh>
            <uri>model://tryd/meshes/l4_lh2.STL</uri>
          </mesh>
        </geometry>
        <surface>
          <friction>
            <ode>
              <mu>0.6</mu>
              <mu2>0.6</mu2>
            </ode>
          </friction>
        </surface>
      </collision>
    </link>

    <joint name='j4_lh3' type='revolute'>
      <pose relative_to='l2_lh'>0.101172545948959 0 0.0377904213552296 0 0 0</pose>
      <parent>l2_lh</parent>
      <child>l4_lh3</child>
      <axis>
        <xyz>0 1 0</xyz>
        <limit>
          <lower>-1.57</lower>
          <upper>1.57</upper>
          <effort>5</effort>
          <velocity>2</velocity>
        </limit>
      </axis>
    </joint>

    <link name='l4_lh3'>
      <pose relative_to='j4_lh3'>0 0 0 0 0 0</pose>
      <inertial>
        <pose>-0.0572424609164394 0.0349999939510118 0.0437112317178444 0 0 0</pose>
        <mass>0.505772946198786</mass>
        <inertia>
          <ixx>0.000551</ixx>
          <ixy>0.000000</ixy>
          <ixz>-0.000616</ixz>
          <iyy>0.001703</iyy>
          <iyz>0.000000</iyz>
          <izz>0.001342</izz>
        </inertia>
      </inertial>
      <visual name='v'>
        <geometry>
          <mesh>
            <uri>model://tryd/meshes/l4_lh3.STL</uri>
          </mesh>
        </geometry>
      </visual>
      <collision name='c'>
        <geometry>
          <mesh>
            <uri>model://tryd/meshes/l4_lh3.STL</uri>
          </mesh>
        </geometry>
        <surface>
          <friction>
            <ode>
              <mu>0.6</mu>
              <mu2>0.6</mu2>
            </ode>
          </friction>
        </surface>
      </collision>
    </link>

    <!-- IMU -->
    <link name="imu_link">
      <pose relative_to='base_link'>0 0 0 0 0 0</pose>
      <inertial>
        <mass>0.001</mass>
        <inertia>
          <ixx>0.0001</ixx>
          <ixy>0</ixy>
          <ixz>0</ixz>
          <iyy>0.0001</iyy>
          <iyz>0</iyz>
          <izz>0.0001</izz>
        </inertia>
      </inertial>
      <visual name="v">
        <geometry>
          <box>
            <size>0.001 0.001 0.001</size>
          </box>
        </geometry>
      </visual>
      <sensor name="imu_sensor" type="imu">
        <always_on>1</always_on>
        <update_rate>400</update_rate>
        <visualize>1</visualize>
        <topic>trunk_imu</topic>
      </sensor>
    </link>
    <joint name="imu_joint" type="fixed">
      <parent>base_link</parent>
      <child>imu_link</child>
    </joint>

    <plugin filename="gz-sim-joint-state-publisher-system" name="gz::sim::systems::JointStatePublisher"></plugin>

    

  </model>
</sdf>