<?xml version='1.0'?>
<sdf version='1.7'>
  <model name='tryd'>
    
    <!-- ========================================== -->
    <!-- BASE SECTON -->
    <!-- ========================================== -->
    <link name='base_footprint'>
      <pose>0 0 0 0 0 0</pose>
    </link>

    <joint name='base_joint' type='fixed'>
      <pose relative_to='base_footprint'>0 0 0 0 0 0</pose>
      <parent>base_footprint</parent>
      <child>base_link</child>
    </joint>

    <link name='base_link'>
      <pose relative_to='base_joint'>0 0 0 0 0 0</pose>
      <inertial>
        <pose>-0.000009 0 -0.01 0 0 0</pose>
        <mass>5.51387</mass>
        <inertia>
          <ixx>0.0134469</ixx><ixy>-2.59e-08</ixy><ixz>-3.51e-08</ixz>
          <iyy>0.165475</iyy><iyz>-1.62e-11</iyz><izz>0.178554</izz>
        </inertia>
      </inertial>
      <visual name='base_link_visual'>
        <geometry><mesh><uri>model://tryd/meshes/base_link.STL</uri></mesh></geometry>
        <material><script><name>Gazebo/White</name><uri>file://media/materials/scripts/gazebo.material</uri></script></material>
      </visual>
      <collision name='base_link_collision'>
        <geometry><mesh><uri>model://tryd/meshes/base_link.STL</uri></mesh></geometry>
      </collision>
    </link>

    <!-- ========================================== -->
    <!-- RIGHT FRONT (RF) LEG -->
    <!-- ========================================== -->
    <joint name='j2_rf' type='revolute'>
      <pose relative_to='base_link'>0.24 -0.128 -0.01 0 0 0</pose>
      <parent>base_link</parent><child>l2_rf</child>
      <axis><xyz>0 1 0</xyz><limit><lower>-0.87</lower><upper>0.87</upper><effort>100</effort><velocity>50</velocity></limit></axis>
    </joint>
    <link name='l2_rf'>
      <pose relative_to='j2_rf'>0 0 0 0 0 0</pose>
      <inertial><pose>0 -0.029195 0 0 0 0</pose><mass>0.196609</mass><inertia><ixx>0.000799</ixx><iyy>0.001288</iyy><izz>0.000799</izz></inertia></inertial>
      <visual name='v'><geometry><mesh><uri>model://tryd/meshes/l2_rf.STL</uri></mesh></geometry><material><script><name>Gazebo/White</name><uri>file://media/materials/scripts/gazebo.material</uri></script></material></visual>
      <collision name='c'><geometry><mesh><uri>model://tryd/meshes/l2_rf.STL</uri></mesh></geometry></collision>
    </link>

    <joint name='j1_rf' type='revolute'>
      <pose relative_to='l2_rf'>0 -0.021 0 0 0 0</pose>
      <parent>l2_rf</parent><child>l1_rf</child>
      <axis><xyz>0 1 0</xyz><limit><lower>-1</lower><upper>1</upper></limit></axis>
    </joint>
    <link name='l1_rf'>
      <pose relative_to='j1_rf'>0 0 0 0 0 0</pose>
      <inertial><pose>0 -0.016138 0 0 0 0</pose><mass>0.035424</mass><inertia><ixx>1.2e-05</ixx><iyy>1.5e-05</iyy><izz>1.2e-05</izz></inertia></inertial>
      <visual name='v'><geometry><mesh><uri>model://tryd/meshes/l1_rf.STL</uri></mesh></geometry><material><script><name>Gazebo/Grey</name><uri>file://media/materials/scripts/gazebo.material</uri></script></material></visual>
      <collision name='c'><geometry><mesh><uri>model://tryd/meshes/l1_rf.STL</uri></mesh></geometry></collision>
    </link>

    <!-- RF BRANCH 1 -->
    <joint name='j3_rf1' type='revolute'><pose relative_to='l1_rf'>0.022147 0 0.020237 0 0 0</pose><parent>l1_rf</parent><child>l3_rf1</child><axis><xyz>0 1 0</xyz></axis></joint>
    <link name='l3_rf1'><pose relative_to='j3_rf1'>0 0 0 0 0 0</pose>
      <inertial><pose>-0.039891 -0.014 0.048288 0 0 0</pose><mass>0.055732</mass><inertia><ixx>2.9e-05</ixx><ixz>-3.2e-05</ixz><iyy>7.1e-05</iyy><izz>4.4e-05</izz></inertia></inertial>
      <visual name='v'><geometry><mesh><uri>model://tryd/meshes/l3_rf1.STL</uri></mesh></geometry></visual><collision name='c'><geometry><mesh><uri>model://tryd/meshes/l3_rf1.STL</uri></mesh></geometry></collision>
    </link>
    <joint name='j4_rf1' type='revolute'><pose relative_to='l2_rf'>-0.083314 0 0.068723 0 0 0</pose><parent>l2_rf</parent><child>l4_rf1</child><axis><xyz>0 1 0</xyz></axis></joint>
    <link name='l4_rf1'><pose relative_to='j4_rf1'>0 0 0 0 0 0</pose>
      <inertial><pose>-0.009259 -0.035 -0.071426 0 0 0</pose><mass>0.505773</mass><inertia><ixx>0.001678</ixx><ixz>-3.5e-05</ixz><iyy>0.001703</iyy><izz>0.000215</izz></inertia></inertial>
      <visual name='v'><geometry><mesh><uri>model://tryd/meshes/l4_rf1.STL</uri></mesh></geometry></visual><collision name='c'><geometry><mesh><uri>model://tryd/meshes/l4_rf1.STL</uri></mesh></geometry></collision>
    </link>

    <!-- RF BRANCH 2 -->
    <joint name='j3_rf2' type='revolute'><pose relative_to='l1_rf'>-0.028599 0 0.009061 0 0 0</pose><parent>l1_rf</parent><child>l3_rf2</child><axis><xyz>0 1 0</xyz></axis></joint>
    <link name='l3_rf2'><pose relative_to='j3_rf2'>0 0 0 0 0 0</pose>
      <inertial><pose>-0.021873 -0.014 -0.05869 0 0 0</pose><mass>0.055732</mass><inertia><ixx>6.8e-05</ixx><ixz>9e-06</ixz><iyy>7.1e-05</iyy><izz>6e-06</izz></inertia></inertial>
      <visual name='v'><geometry><mesh><uri>model://tryd/meshes/l3_rf2.STL</uri></mesh></geometry></visual><collision name='c'><geometry><mesh><uri>model://tryd/meshes/l3_rf2.STL</uri></mesh></geometry></collision>
    </link>
    <joint name='j4_rf2' type='revolute'><pose relative_to='l2_rf'>-0.017859 0 -0.106513 0 0 0</pose><parent>l2_rf</parent><child>l4_rf2</child><axis><xyz>0 1 0</xyz></axis></joint>
    <link name='l4_rf2'><pose relative_to='j4_rf2'>0 0 0 0 0 0</pose>
      <inertial><pose>0.066486 -0.035 0.027695 0 0 0</pose><mass>0.505773</mass><inertia><ixx>0.000611</ixx><ixz>0.000651</ixz><iyy>0.001703</iyy><izz>0.001282</izz></inertia></inertial>
      <visual name='v'><geometry><mesh><uri>model://tryd/meshes/l4_rf2.STL</uri></mesh></geometry></visual><collision name='c'><geometry><mesh><uri>model://tryd/meshes/l4_rf2.STL</uri></mesh></geometry></collision>
    </link>

    <!-- RF BRANCH 3 -->
    <joint name='j3_rf3' type='revolute'><pose relative_to='l1_rf'>0.006452 0 -0.029298 0 0 0</pose><parent>l1_rf</parent><child>l3_rf3</child><axis><xyz>0 1 0</xyz></axis></joint>
    <link name='l3_rf3'><pose relative_to='j3_rf3'>0 0 0 0 0 0</pose>
      <inertial><pose>0.061764 -0.014 0.010402 0 0 0</pose><mass>0.055732</mass><inertia><ixx>1.3e-05</ixx><ixz>2.2e-05</ixz><iyy>7.1e-05</iyy><izz>6.1e-05</izz></inertia></inertial>
      <visual name='v'><geometry><mesh><uri>model://tryd/meshes/l3_rf3.STL</uri></mesh></geometry></visual><collision name='c'><geometry><mesh><uri>model://tryd/meshes/l3_rf3.STL</uri></mesh></geometry></collision>
    </link>
    <joint name='j4_rf3' type='revolute'><pose relative_to='l2_rf'>0.101173 0 0.03779 0 0 0</pose><parent>l2_rf</parent><child>l4_rf3</child><axis><xyz>0 1 0</xyz></axis></joint>
    <link name='l4_rf3'><pose relative_to='j4_rf3'>0 0 0 0 0 0</pose>
      <inertial><pose>-0.057227 -0.035 0.043731 0 0 0</pose><mass>0.505773</mass><inertia><ixx>0.000551</ixx><ixz>-0.000616</ixz><iyy>0.001703</iyy><izz>0.001342</izz></inertia></inertial>
      <visual name='v'><geometry><mesh><uri>model://tryd/meshes/l4_rf3.STL</uri></mesh></geometry></visual><collision name='c'><geometry><mesh><uri>model://tryd/meshes/l4_rf3.STL</uri></mesh></geometry></collision>
    </link>

    <!-- ========================================== -->
    <!-- LEFT FRONT (LF) LEG -->
    <!-- ========================================== -->
    <joint name='j2_lf' type='revolute'>
      <pose relative_to='base_link'>0.24 0.128 -0.01 0 0 0</pose>
      <parent>base_link</parent><child>l2_lf</child>
      <axis><xyz>0 1 0</xyz><limit><lower>-50</lower><upper>50</upper></limit></axis>
    </joint>
    <link name='l2_lf'>
      <pose relative_to='j2_lf'>0 0 0 0 0 0</pose>
      <inertial><pose>-0 0.029195 0 0 0 0</pose><mass>0.196609</mass><inertia><ixx>0.000799</ixx><iyy>0.001288</iyy><izz>0.000799</izz></inertia></inertial>
      <visual name='v'><geometry><mesh><uri>model://tryd/meshes/l2_lf.STL</uri></mesh></geometry><material><script><name>Gazebo/White</name><uri>file://media/materials/scripts/gazebo.material</uri></script></material></visual>
      <collision name='c'><geometry><mesh><uri>model://tryd/meshes/l2_lf.STL</uri></mesh></geometry></collision>
    </link>
    <joint name='j1_lf' type='revolute'>
      <pose relative_to='l2_lf'>0 0.021 0 0 0 0</pose>
      <parent>l2_lf</parent><child>l1_lf</child>
      <axis><xyz>0 1 0</xyz><limit><lower>-1</lower><upper>1</upper></limit></axis>
    </joint>
    <link name='l1_lf'>
      <pose relative_to='j1_lf'>0 0 0 0 0 0</pose>
      <inertial><pose>0 0.016138 0 0 0 0</pose><mass>0.035424</mass><inertia><ixx>1.2e-05</ixx><iyy>1.5e-05</iyy><izz>1.2e-05</izz></inertia></inertial>
      <visual name='v'><geometry><mesh><uri>model://tryd/meshes/l1_lf.STL</uri></mesh></geometry></visual><collision name='c'><geometry><mesh><uri>model://tryd/meshes/l1_lf.STL</uri></mesh></geometry></collision>
    </link>

    <!-- LF BRANCHES -->
    <joint name='j3_lf1' type='revolute'><pose relative_to='l1_lf'>0.02214 0 0.020244 0 0 0</pose><parent>l1_lf</parent><child>l3_lf1</child><axis><xyz>0 1 0</xyz></axis></joint>
    <link name='l3_lf1'><pose relative_to='j3_lf1'>0 0 0 0 0 0</pose>
      <visual name='v'><geometry><mesh><uri>model://tryd/meshes/l3_lf1.STL</uri></mesh></geometry></visual><collision name='c'><geometry><mesh><uri>model://tryd/meshes/l3_lf1.STL</uri></mesh></geometry></collision>
      <inertial><pose>-0.039891 0.014 0.048288 0 0 0</pose><mass>0.055732</mass><inertia><ixx>2.9e-05</ixx><ixz>-3.2e-05</ixz><iyy>7.1e-05</iyy><izz>4.4e-05</izz></inertia></inertial>
    </link>
    <joint name='j4_lf1' type='revolute'><pose relative_to='l2_lf'>-0.083314 0 0.068723 0 0 0</pose><parent>l2_lf</parent><child>l4_lf1</child><axis><xyz>0 1 0</xyz></axis></joint>
    <link name='l4_lf1'><pose relative_to='j4_lf1'>0 0 0 0 0 0</pose>
      <visual name='v'><geometry><mesh><uri>model://tryd/meshes/l4_lf1.STL</uri></mesh></geometry></visual><collision name='c'><geometry><mesh><uri>model://tryd/meshes/l4_lf1.STL</uri></mesh></geometry></collision>
      <inertial><pose>-0.009234 0.035 -0.071429 0 0 0</pose><mass>0.505773</mass><inertia><ixx>0.001678</ixx><ixz>-3.5e-05</ixz><iyy>0.001703</iyy><izz>0.000215</izz></inertia></inertial>
    </link>

    <joint name='j3_lf2' type='revolute'><pose relative_to='l1_lf'>-0.028602 0 0.009051 0 0 0</pose><parent>l1_lf</parent><child>l3_lf2</child><axis><xyz>0 1 0</xyz></axis></joint>
    <link name='l3_lf2'><pose relative_to='j3_lf2'>0 0 0 0 0 0</pose>
      <visual name='v'><geometry><mesh><uri>model://tryd/meshes/l3_lf2.STL</uri></mesh></geometry></visual><collision name='c'><geometry><mesh><uri>model://tryd/meshes/l3_lf2.STL</uri></mesh></geometry></collision>
      <inertial><pose>-0.021873 0.014 -0.05869 0 0 0</pose><mass>0.055732</mass><inertia><ixx>6.8e-05</ixx><ixz>9e-06</ixz><iyy>7.1e-05</iyy><izz>6e-06</izz></inertia></inertial>
    </link>
    <joint name='j4_lf2' type='revolute'><pose relative_to='l2_lf'>-0.017859 0 -0.106513 0 0 0</pose><parent>l2_lf</parent><child>l4_lf2</child><axis><xyz>0 1 0</xyz></axis></joint>
    <link name='l4_lf2'><pose relative_to='j4_lf2'>0 0 0 0 0 0</pose>
      <visual name='v'><geometry><mesh><uri>model://tryd/meshes/l4_lf2.STL</uri></mesh></geometry></visual><collision name='c'><geometry><mesh><uri>model://tryd/meshes/l4_lf2.STL</uri></mesh></geometry></collision>
      <inertial><pose>0.066476 0.035 0.027718 0 0 0</pose><mass>0.505773</mass><inertia><ixx>0.000611</ixx><ixz>0.000651</ixz><iyy>0.001703</iyy><izz>0.001282</izz></inertia></inertial>
    </link>

    <joint name='j3_lf3' type='revolute'><pose relative_to='l1_lf'>0.006462 0 -0.029296 0 0 0</pose><parent>l1_lf</parent><child>l3_lf3</child><axis><xyz>0 1 0</xyz></axis></joint>
    <link name='l3_lf3'><pose relative_to='j3_lf3'>0 0 0 0 0 0</pose>
      <visual name='v'><geometry><mesh><uri>model://tryd/meshes/l3_lf3.STL</uri></mesh></geometry></visual><collision name='c'><geometry><mesh><uri>model://tryd/meshes/l3_lf3.STL</uri></mesh></geometry></collision>
      <inertial><pose>0.061764 0.014 0.010402 0 0 0</pose><mass>0.055732</mass><inertia><ixx>1.3e-05</ixx><ixz>2.2e-05</ixz><iyy>7.1e-05</iyy><izz>6.1e-05</izz></inertia></inertial>
    </link>
    <joint name='j4_lf3' type='revolute'><pose relative_to='l2_lf'>0.101173 0 0.03779 0 0 0</pose><parent>l2_lf</parent><child>l4_lf3</child><axis><xyz>0 1 0</xyz></axis></joint>
    <link name='l4_lf3'><pose relative_to='j4_lf3'>0 0 0 0 0 0</pose>
      <visual name='v'><geometry><mesh><uri>model://tryd/meshes/l4_lf3.STL</uri></mesh></geometry></visual><collision name='c'><geometry><mesh><uri>model://tryd/meshes/l4_lf3.STL</uri></mesh></geometry></collision>
      <inertial><pose>-0.057242 0.035 0.043711 0 0 0</pose><mass>0.505773</mass><inertia><ixx>0.000551</ixx><ixz>-0.000616</ixz><iyy>0.001703</iyy><izz>0.001342</izz></inertia></inertial>
    </link>

    <!-- ========================================== -->
    <!-- RIGHT HIND (RH) LEG -->
    <!-- ========================================== -->
    <joint name='j2_rh' type='revolute'><pose relative_to='base_link'>-0.24 -0.128 -0.01 0 0 0</pose><parent>base_link</parent><child>l2_rh</child><axis><xyz>0 1 0</xyz></axis></joint>
    <link name='l2_rh'>
      <pose relative_to='j2_rh'>0 0 0 0 0 0</pose>
      <inertial><pose>0 -0.029195 0 0 0 0</pose><mass>0.196609</mass><inertia><ixx>0.000799</ixx><iyy>0.001288</iyy><izz>0.000799</izz></inertia></inertial>
      <visual name='v'><geometry><mesh><uri>model://tryd/meshes/l2_rh.STL</uri></mesh></geometry><material><script><name>Gazebo/White</name><uri>file://media/materials/scripts/gazebo.material</uri></script></material></visual><collision name='c'><geometry><mesh><uri>model://tryd/meshes/l2_rh.STL</uri></mesh></geometry></collision>
    </link>
    <joint name='j1_rh' type='revolute'><pose relative_to='l2_rh'>0 -0.021 0 0 0 0</pose><parent>l2_rh</parent><child>l1_rh</child><axis><xyz>0 1 0</xyz></axis></joint>
    <link name='l1_rh'><pose relative_to='j1_rh'>0 0 0 0 0 0</pose>
      <visual name='v'><geometry><mesh><uri>model://tryd/meshes/l1_rh.STL</uri></mesh></geometry></visual><collision name='c'><geometry><mesh><uri>model://tryd/meshes/l1_rh.STL</uri></mesh></geometry></collision>
      <inertial><pose>0 -0.016138 0 0 0 0</pose><mass>0.035424</mass><inertia><ixx>1.2e-05</ixx><iyy>1.5e-05</iyy><izz>1.2e-05</izz></inertia></inertial>
    </link>

    <!-- RH BRANCHES -->
    <joint name='j3_rh1' type='revolute'><pose relative_to='l1_rh'>0.022147 0 0.020237 0 0 0</pose><parent>l1_rh</parent><child>l3_rh1</child><axis><xyz>0 1 0</xyz></axis></joint>
    <link name='l3_rh1'><pose relative_to='j3_rh1'>0 0 0 0 0 0</pose>
      <visual name='v'><geometry><mesh><uri>model://tryd/meshes/l3_rh1.STL</uri></mesh></geometry></visual><collision name='c'><geometry><mesh><uri>model://tryd/meshes/l3_rh1.STL</uri></mesh></geometry></collision>
      <inertial><pose>-0.039891 -0.014 0.048288 0 0 0</pose><mass>0.055732</mass><inertia><ixx>2.9e-05</ixx><ixz>-3.2e-05</ixz><iyy>7.1e-05</iyy><izz>4.4e-05</izz></inertia></inertial>
    </link>
    <joint name='j4_rh1' type='revolute'><pose relative_to='l2_rh'>-0.083314 0 0.068723 0 0 0</pose><parent>l2_rh</parent><child>l4_rh1</child><axis><xyz>0 1 0</xyz></axis></joint>
    <link name='l4_rh1'><pose relative_to='j4_rh1'>0 0 0 0 0 0</pose>
      <visual name='v'><geometry><mesh><uri>model://tryd/meshes/l4_rh1.STL</uri></mesh></geometry></visual><collision name='c'><geometry><mesh><uri>model://tryd/meshes/l4_rh1.STL</uri></mesh></geometry></collision>
      <inertial><pose>-0.009259 -0.035 -0.071426 0 0 0</pose><mass>0.505773</mass><inertia><ixx>0.001678</ixx><ixz>-3.5e-05</ixz><iyy>0.001703</iyy><izz>0.000215</izz></inertia></inertial>
    </link>

    <joint name='j3_rh2' type='revolute'><pose relative_to='l1_rh'>-0.028599 0 0.009061 0 0 0</pose><parent>l1_rh</parent><child>l3_rh2</child><axis><xyz>0 1 0</xyz></axis></joint>
    <link name='l3_rh2'><pose relative_to='j3_rh2'>0 0 0 0 0 0</pose>
      <visual name='v'><geometry><mesh><uri>model://tryd/meshes/l3_rh2.STL</uri></mesh></geometry></visual><collision name='c'><geometry><mesh><uri>model://tryd/meshes/l3_rh2.STL</uri></mesh></geometry></collision>
      <inertial><pose>-0.021873 -0.014 -0.05869 0 0 0</pose><mass>0.055732</mass><inertia><ixx>6.8e-05</ixx><ixz>9e-06</ixz><iyy>7.1e-05</iyy><izz>6e-06</izz></inertia></inertial>
    </link>
    <joint name='j4_rh2' type='revolute'><pose relative_to='l2_rh'>-0.017859 0 -0.106513 0 0 0</pose><parent>l2_rh</parent><child>l4_rh2</child><axis><xyz>0 1 0</xyz></axis></joint>
    <link name='l4_rh2'><pose relative_to='j4_rh2'>0 0 0 0 0 0</pose>
      <visual name='v'><geometry><mesh><uri>model://tryd/meshes/l4_rh2.STL</uri></mesh></geometry></visual><collision name='c'><geometry><mesh><uri>model://tryd/meshes/l4_rh2.STL</uri></mesh></geometry></collision>
      <inertial><pose>0.066486 -0.035 0.027695 0 0 0</pose><mass>0.505773</mass><inertia><ixx>0.000611</ixx><ixz>0.000651</ixz><iyy>0.001703</iyy><izz>0.001282</izz></inertia></inertial>
    </link>

    <joint name='j3_rh3' type='revolute'><pose relative_to='l1_rh'>0.006452 0 -0.029298 0 0 0</pose><parent>l1_rh</parent><child>l3_rh3</child><axis><xyz>0 1 0</xyz></axis></joint>
    <link name='l3_rh3'><pose relative_to='j3_rh3'>0 0 0 0 0 0</pose>
      <visual name='v'><geometry><mesh><uri>model://tryd/meshes/l3_rh3.STL</uri></mesh></geometry></visual><collision name='c'><geometry><mesh><uri>model://tryd/meshes/l3_rh3.STL</uri></mesh></geometry></collision>
      <inertial><pose>0.061764 -0.014 0.010402 0 0 0</pose><mass>0.055732</mass><inertia><ixx>1.3e-05</ixx><ixz>2.2e-05</ixz><iyy>7.1e-05</iyy><izz>6.1e-05</izz></inertia></inertial>
    </link>
    <joint name='j4_rh3' type='revolute'><pose relative_to='l2_rh'>0.101173 0 0.03779 0 0 0</pose><parent>l2_rh</parent><child>l4_rh3</child><axis><xyz>0 1 0</xyz></axis></joint>
    <link name='l4_rh3'><pose relative_to='j4_rh3'>0 0 0 0 0 0</pose>
      <visual name='v'><geometry><mesh><uri>model://tryd/meshes/l4_rh3.STL</uri></mesh></geometry></visual><collision name='c'><geometry><mesh><uri>model://tryd/meshes/l4_rh3.STL</uri></mesh></geometry></collision>
      <inertial><pose>-0.057227 -0.035 0.043731 0 0 0</pose><mass>0.505773</mass><inertia><ixx>0.000551</ixx><ixz>-0.000616</ixz><iyy>0.001703</iyy><izz>0.001342</izz></inertia></inertial>
    </link>

    <!-- ========================================== -->
    <!-- LEFT HIND (LH) LEG -->
    <!-- ========================================== -->
    <joint name='j2_lh' type='revolute'><pose relative_to='base_link'>-0.24 0.128 -0.01 0 0 0</pose><parent>base_link</parent><child>l2_lh</child><axis><xyz>0 1 0</xyz></axis></joint>
    <link name='l2_lh'>
      <pose relative_to='j2_lh'>0 0 0 0 0 0</pose>
      <inertial><pose>0 0.029195 0 0 0 0</pose><mass>0.196609</mass><inertia><ixx>0.000799</ixx><iyy>0.001288</iyy><izz>0.000799</izz></inertia></inertial>
      <visual name='v'><geometry><mesh><uri>model://tryd/meshes/l2_lh.STL</uri></mesh></geometry><material><script><name>Gazebo/White</name><uri>file://media/materials/scripts/gazebo.material</uri></script></material></visual><collision name='c'><geometry><mesh><uri>model://tryd/meshes/l2_lh.STL</uri></mesh></geometry></collision>
    </link>
    <joint name='j1_lh' type='revolute'><pose relative_to='l2_lh'>0 0.021 0 0 0 0</pose><parent>l2_lh</parent><child>l1_lh</child><axis><xyz>0 1 0</xyz></axis></joint>
    <link name='l1_lh'><pose relative_to='j1_lh'>0 0 0 0 0 0</pose>
      <visual name='v'><geometry><mesh><uri>model://tryd/meshes/l1_lh.STL</uri></mesh></geometry></visual><collision name='c'><geometry><mesh><uri>model://tryd/meshes/l1_lh.STL</uri></mesh></geometry></collision>
      <inertial><pose>0 0.016138 0 0 0 0</pose><mass>0.035424</mass><inertia><ixx>1.2e-05</ixx><iyy>1.5e-05</iyy><izz>1.2e-05</izz></inertia></inertial>
    </link>

    <!-- LH BRANCHES -->
    <joint name='j3_lh1' type='revolute'><pose relative_to='l1_lh'>0.02214 0 0.020244 0 0 0</pose><parent>l1_lh</parent><child>l3_lh1</child><axis><xyz>0 1 0</xyz></axis></joint>
    <link name='l3_lh1'><pose relative_to='j3_lh1'>0 0 0 0 0 0</pose>
      <visual name='v'><geometry><mesh><uri>model://tryd/meshes/l3_lh1.STL</uri></mesh></geometry></visual><collision name='c'><geometry><mesh><uri>model://tryd/meshes/l3_lh1.STL</uri></mesh></geometry></collision>
      <inertial><pose>-0.039891 0.014 0.048288 0 0 0</pose><mass>0.055732</mass><inertia><ixx>2.9e-05</ixx><ixz>-3.2e-05</ixz><iyy>7.1e-05</iyy><izz>4.4e-05</izz></inertia></inertial>
    </link>
    <joint name='j4_lh1' type='revolute'><pose relative_to='l2_lh'>-0.083314 0 0.068723 0 0 0</pose><parent>l2_lh</parent><child>l4_lh1</child><axis><xyz>0 1 0</xyz></axis></joint>
    <link name='l4_lh1'><pose relative_to='j4_lh1'>0 0 0 0 0 0</pose>
      <visual name='v'><geometry><mesh><uri>model://tryd/meshes/l4_lh1.STL</uri></mesh></geometry></visual><collision name='c'><geometry><mesh><uri>model://tryd/meshes/l4_lh1.STL</uri></mesh></geometry></collision>
      <inertial><pose>-0.009234 0.035 -0.071429 0 0 0</pose><mass>0.505773</mass><inertia><ixx>0.001678</ixx><ixz>-3.5e-05</ixz><iyy>0.001703</iyy><izz>0.000215</izz></inertia></inertial>
    </link>

    <joint name='j3_lh2' type='revolute'><pose relative_to='l1_lh'>-0.028602 0 0.009051 0 0 0</pose><parent>l1_lh</parent><child>l3_lh2</child><axis><xyz>0 1 0</xyz></axis></joint>
    <link name='l3_lh2'><pose relative_to='j3_lh2'>0 0 0 0 0 0</pose>
      <visual name='v'><geometry><mesh><uri>model://tryd/meshes/l3_lh2.STL</uri></mesh></geometry></visual><collision name='c'><geometry><mesh><uri>model://tryd/meshes/l3_lh2.STL</uri></mesh></geometry></collision>
      <inertial><pose>-0.021873 0.014 -0.05869 0 0 0</pose><mass>0.055732</mass><inertia><ixx>6.8e-05</ixx><ixz>9e-06</ixz><iyy>7.1e-05</iyy><izz>6e-06</izz></inertia></inertial>
    </link>
    <joint name='j4_lh2' type='revolute'><pose relative_to='l2_lh'>-0.017859 0 -0.106513 0 0 0</pose><parent>l2_lh</parent><child>l4_lh2</child><axis><xyz>0 1 0</xyz></axis></joint>
    <link name='l4_lh2'><pose relative_to='j4_lh2'>0 0 0 0 0 0</pose>
      <visual name='v'><geometry><mesh><uri>model://tryd/meshes/l4_lh2.STL</uri></mesh></geometry></visual><collision name='c'><geometry><mesh><uri>model://tryd/meshes/l4_lh2.STL</uri></mesh></geometry></collision>
      <inertial><pose>0.066476 0.035 0.027718 0 0 0</pose><mass>0.505773</mass><inertia><ixx>0.000611</ixx><ixz>0.000651</ixz><iyy>0.001703</iyy><izz>0.001282</izz></inertia></inertial>
    </link>

    <joint name='j3_lh3' type='revolute'><pose relative_to='l1_lh'>0.006462 0 -0.029296 0 0 0</pose><parent>l1_lh</parent><child>l3_lh3</child><axis><xyz>0 1 0</xyz></axis></joint>
    <link name='l3_lh3'><pose relative_to='j3_lh3'>0 0 0 0 0 0</pose>
      <visual name='v'><geometry><mesh><uri>model://tryd/meshes/l3_lh3.STL</uri></mesh></geometry></visual><collision name='c'><geometry><mesh><uri>model://tryd/meshes/l3_lh3.STL</uri></mesh></geometry></collision>
      <inertial><pose>0.061764 0.014 0.010402 0 0 0</pose><mass>0.055732</mass><inertia><ixx>1.3e-05</ixx><ixz>2.2e-05</ixz><iyy>7.1e-05</iyy><izz>6.1e-05</izz></inertia></inertial>
    </link>
    <joint name='j4_lh3' type='revolute'><pose relative_to='l2_lh'>0.101173 0 0.03779 0 0 0</pose><parent>l2_lh</parent><child>l4_lh3</child><axis><xyz>0 1 0</xyz></axis></joint>
    <link name='l4_lh3'><pose relative_to='j4_lh3'>0 0 0 0 0 0</pose>
      <visual name='v'><geometry><mesh><uri>model://tryd/meshes/l4_lh3.STL</uri></mesh></geometry></visual><collision name='c'><geometry><mesh><uri>model://tryd/meshes/l4_lh3.STL</uri></mesh></geometry></collision>
      <inertial><pose>-0.057242 0.035 0.043711 0 0 0</pose><mass>0.505773</mass><inertia><ixx>0.000551</ixx><ixz>-0.000616</ixz><iyy>0.001703</iyy><izz>0.001342</izz></inertia></inertial>
    </link>

    <!-- IMU SENSOR -->
    <link name="imu_link">
      <pose relative_to='base_link'>0 0 0 0 0 0</pose>
      <inertial>
        <mass>0.001</mass>
        <inertia><ixx>0.0001</ixx><ixy>0</ixy><ixz>0</ixz><iyy>0.0001</iyy><iyz>0</iyz><izz>0.0001</izz></inertia>
      </inertial>
      <visual name="visual"><geometry><box><size>0.001 0.001 0.001</size></box></geometry></visual>
      <sensor name="imu_sensor" type="imu">
        <always_on>1</always_on>
        <update_rate>400</update_rate>
        <visualize>1</visualize>
        <topic>trunk_imu</topic>
      </sensor>
    </link>
    <joint name="imu_joint" type="fixed">
      <parent>base_link</parent>
      <child>imu_link</child>
    </joint>

    <!-- PLUGINS -->
    <plugin filename="gz-sim-joint-state-publisher-system" name="gz::sim::systems::JointStatePublisher"></plugin>

    <!-- DETACHABLE JOINTS FOR CLOSED LOOPS (Run at simulation start) -->
    <!-- RF1 -->
    <plugin filename="gz-sim-detachable-joint-system" name="gz::sim::systems::DetachableJoint">
      <parent_link>l4_rf1</parent_link>
      <child_model>tryd</child_model>
      <child_link>l3_rf1</child_link>
      <!-- Child pose is the offset from child link origin -->
      <!-- Mapping from: position -0.06748 -0.021 0.08429 -->
      <child_pose>-0.06748 -0.021 0.08429 0 0 0</child_pose>
    </plugin>
    <!-- RF2 -->
    <plugin filename="gz-sim-detachable-joint-system" name="gz::sim::systems::DetachableJoint">
      <parent_link>l4_rf2</parent_link>
      <child_model>tryd</child_model>
      <child_link>l3_rf2</child_link>
      <child_pose>-0.03925 -0.021 -0.10059 0 0 0</child_pose>
    </plugin>
    <!-- RF3 -->
    <plugin filename="gz-sim-detachable-joint-system" name="gz::sim::systems::DetachableJoint">
      <parent_link>l4_rf3</parent_link>
      <child_model>tryd</child_model>
      <child_link>l3_rf3</child_link>
      <child_pose>0.10674 -0.021 0.0163 0 0 0</child_pose>
    </plugin>
    <!-- LF1 -->
    <plugin filename="gz-sim-detachable-joint-system" name="gz::sim::systems::DetachableJoint">
      <parent_link>l4_lf1</parent_link>
      <child_model>tryd</child_model>
      <child_link>l3_lf1</child_link>
      <child_pose>-0.06748 0.021 0.08429 0 0 0</child_pose>
    </plugin>
    <!-- LF2 -->
    <plugin filename="gz-sim-detachable-joint-system" name="gz::sim::systems::DetachableJoint">
      <parent_link>l4_lf2</parent_link>
      <child_model>tryd</child_model>
      <child_link>l3_lf2</child_link>
      <child_pose>-0.03925 0.021 -0.10059 0 0 0</child_pose>
    </plugin>
    <!-- LF3 -->
    <plugin filename="gz-sim-detachable-joint-system" name="gz::sim::systems::DetachableJoint">
      <parent_link>l4_lf3</parent_link>
      <child_model>tryd</child_model>
      <child_link>l3_lf3</child_link>
      <child_pose>0.10674 0.021 0.0163 0 0 0</child_pose>
    </plugin>
    <!-- RH1 -->
    <plugin filename="gz-sim-detachable-joint-system" name="gz::sim::systems::DetachableJoint">
      <parent_link>l4_rh1</parent_link>
      <child_model>tryd</child_model>
      <child_link>l3_rh1</child_link>
      <child_pose>-0.06748 -0.021 0.08429 0 0 0</child_pose>
    </plugin>
    <!-- RH2 -->
    <plugin filename="gz-sim-detachable-joint-system" name="gz::sim::systems::DetachableJoint">
      <parent_link>l4_rh2</parent_link>
      <child_model>tryd</child_model>
      <child_link>l3_rh2</child_link>
      <child_pose>-0.03925 -0.021 -0.10059 0 0 0</child_pose>
    </plugin>
    <!-- RH3 -->
    <plugin filename="gz-sim-detachable-joint-system" name="gz::sim::systems::DetachableJoint">
      <parent_link>l4_rh3</parent_link>
      <child_model>tryd</child_model>
      <child_link>l3_rh3</child_link>
      <child_pose>0.10674 -0.021 0.0163 0 0 0</child_pose>
    </plugin>
    <!-- LH1 -->
    <plugin filename="gz-sim-detachable-joint-system" name="gz::sim::systems::DetachableJoint">
      <parent_link>l4_lh1</parent_link>
      <child_model>tryd</child_model>
      <child_link>l3_lh1</child_link>
      <child_pose>-0.06748 0.021 0.08429 0 0 0</child_pose>
    </plugin>
    <!-- LH2 -->
    <plugin filename="gz-sim-detachable-joint-system" name="gz::sim::systems::DetachableJoint">
      <parent_link>l4_lh2</parent_link>
      <child_model>tryd</child_model>
      <child_link>l3_lh2</child_link>
      <child_pose>-0.03925 0.021 -0.10059 0 0 0</child_pose>
    </plugin>
    <!-- LH3 -->
    <plugin filename="gz-sim-detachable-joint-system" name="gz::sim::systems::DetachableJoint">
      <parent_link>l4_lh3</parent_link>
      <child_model>tryd</child_model>
      <child_link>l3_lh3</child_link>
      <child_pose>0.10674 0.021 0.0163 0 0 0</child_pose>
    </plugin>

  </model>
</sdf>