<?xml version="1.0" encoding="utf-8"?>
<!-- This URDF was automatically created by SolidWorks to URDF Exporter! Originally created by Stephen Brawner (brawner@gmail.com) 
     Commit Version: 1.6.0-4-g7f85cfe  Build Version: 1.6.7995.38578
     For more information, please see http://wiki.ros.org/sw_urdf_exporter -->
<robot name="tryd">
  <link name="base_footprint"/>

  <link name="base_link">
    <inertial>
      <origin xyz="-8.94907244384436E-06 1.56777004396414E-08 -0.0099999786979822" rpy="0 0 0" />
      <mass value="5.51387120943428" />
      <inertia ixx="0.0134468927294375" ixy="-2.59140603594283E-08" ixz="-3.51546984955843E-08" iyy="0.165475287417608" iyz="-1.62022466077164E-11" izz="0.178554327537039" />
    </inertial>
    <visual>
      <origin xyz="0 0 0" rpy="0 0 0" />
      <geometry>
        <mesh filename="package://tryd/meshes/base_link.STL" />
      </geometry>
      <material name="">
        <color rgba="0.898039215686275 0.917647058823529 0.929411764705882 1" />
      </material>
    </visual>
    <collision>
      <origin xyz="0 0 0" rpy="0 0 0" />
      <geometry>
        <mesh filename="package://tryd/meshes/base_link.STL" />
      </geometry>
    </collision>
  </link>
  <joint name="base_joint" type="fixed">
    <parent link="base_footprint"/>
    <child link="base_link"/>
    <axis xyz="0 0 0"/>
    <origin xyz="0 0 0" rpy="0 0 0"/>
  </joint>
  
  <!-- RTF -->  
  <link name="l2_rf">
    <inertial>
      <origin xyz="-2.08804529222562E-10 -0.0291950635463956 2.32404020325735E-11" rpy="0 0 0" />
      <mass value="0.196608556113688" />
      <inertia ixx="0.000799" ixy="0.000000" ixz="0.000000" iyy="0.001288" iyz="0.000000" izz="0.000799" />
    </inertial>
    <visual>
      <origin xyz="0 0 0" rpy="0 0 0" />
      <geometry>
        <mesh filename="package://tryd/meshes/l2_rf.STL" />
      </geometry>
      <material name="">
        <color rgba="0.650980392156863 0.619607843137255 0.588235294117647 1" />
      </material>
    </visual>
    <collision>
      <origin xyz="0 0 0" rpy="0 0 0" />
      <geometry>
        <mesh filename="package://tryd/meshes/l2_rf.STL" />
      </geometry>
    </collision>
  </link>

  <joint name="j2_rf" type="revolute">
    <origin xyz="0.239999999999999 -0.128 -0.0100000000000003" rpy="0 0 0" />
    <parent link="base_link" />
    <child link="l2_rf" />
    <axis xyz="0 1 0" />
    <limit lower="-50" upper="50" effort="100" velocity="50" />
  </joint>

  <link name="l1_rf">
    <inertial>
      <origin xyz="-4.9960036108132E-16 -0.0161380765502627 -2.57744127660233E-16" rpy="0 0 0" />
      <mass value="0.0354240975198173" />
      <inertia ixx="0.000012" ixy="0.000000" ixz="0.000000" iyy="0.000015" iyz="0.000000" izz="0.000012" />
    </inertial>
    <visual>
      <origin xyz="0 0 0" rpy="0 0 0" />
      <geometry>
        <mesh filename="package://tryd/meshes/l1_rf.STL" />
      </geometry>
      <material name="">
        <color rgba="0.898039215686275 0.917647058823529 0.929411764705882 1" />
      </material>
    </visual>
    <collision>
      <origin xyz="0 0 0" rpy="0 0 0" />
      <geometry>
        <mesh filename="package://tryd/meshes/l1_rf.STL" />
      </geometry>
    </collision>
  </link>
  <joint name="j1_rf" type="revolute">
    <origin xyz="0 -0.021 0" rpy="0 0 0" />
    <parent link="l2_rf" />
    <child link="l1_rf" />
    <axis xyz="0 1 0" />
    <limit lower="-1" upper="1" effort="100" velocity="50" />
  </joint>

  <link name="l3_rf1">
    <inertial>
      <origin xyz="-0.0398905245666624 -0.0140000194157354 0.0482877588732501" rpy="0 0 0" />
      <mass value="0.0557316685279916" />
      <inertia ixx="0.000029" ixy="0.000000" ixz="-0.000032" iyy="0.000071" iyz="0.000000" izz="0.000044" />
    </inertial>
    <visual>
      <origin xyz="0 0 0" rpy="0 0 0" />
      <geometry>
        <mesh filename="package://tryd/meshes/l3_rf1.STL" />
      </geometry>
      <material name="">
        <color rgba="0.898039215686275 0.917647058823529 0.929411764705882 1" />
      </material>
    </visual>
    <collision>
      <origin xyz="0 0 0" rpy="0 0 0" />
      <geometry>
        <mesh filename="package://tryd/meshes/l3_rf1.STL" />
      </geometry>
    </collision>
  </link>
  <joint name="j3_rf1" type="revolute">
    <origin xyz="0.022146669767068 0 0.0202367244935637" rpy="0 0 0" />
    <parent link="l1_rf" />
    <child link="l3_rf1" />
    <axis xyz="0 1 0" />
    <limit lower="-1.57" upper="1.57" effort="5" velocity="2" />
  </joint>

  <link name="l3_rf2">
    <inertial>
      <origin xyz="-0.0218731622438092 -0.0140000036638266 -0.0586901178612239" rpy="0 0 0" />
      <mass value="0.0557315697331534" />
      <inertia ixx="0.000068" ixy="0.000000" ixz="0.000009" iyy="0.000071" iyz="0.000000" izz="0.000006" />
    </inertial>
    <visual>
      <origin xyz="0 0 0" rpy="0 0 0" />
      <geometry>
        <mesh filename="package://tryd/meshes/l3_rf2.STL" />
      </geometry>
      <material name="">
        <color rgba="0.898039215686275 0.917647058823529 0.929411764705882 1" />
      </material>
    </visual>
    <collision>
      <origin xyz="0 0 0" rpy="0 0 0" />
      <geometry>
        <mesh filename="package://tryd/meshes/l3_rf2.STL" />
      </geometry>
    </collision>
  </link>
  <joint name="j3_rf2" type="revolute">
    <origin xyz="-0.0285988523843481 0 0.00906121638072432" rpy="0 0 0" />
    <parent link="l1_rf" />
    <child link="l3_rf2" />
    <axis xyz="0 1 0" />
    <limit lower="-1.57" upper="1.57" effort="5" velocity="2" />
  </joint>
  
  <link name="l3_rf3">
    <inertial>
      <origin xyz="0.0617637116997839 -0.0140000031232566 0.0104023387554542" rpy="0 0 0" />
      <mass value="0.0557315625814883" />
      <inertia ixx="0.000013" ixy="0.000000" ixz="0.000022" iyy="0.000071" iyz="0.000000" izz="0.000061" />
    </inertial>
    <visual>
      <origin xyz="0 0 0" rpy="0 0 0" />
      <geometry>
        <mesh filename="package://tryd/meshes/l3_rf3.STL" />
      </geometry>
      <material name="">
        <color rgba="0.898039215686275 0.917647058823529 0.929411764705882 1" />
      </material>
    </visual>
    <collision>
      <origin xyz="0 0 0" rpy="0 0 0" />
      <geometry>
        <mesh filename="package://tryd/meshes/l3_rf3.STL" />
      </geometry>
    </collision>
  </link>
  <joint name="j3_rf3" type="revolute">
    <origin xyz="0.00645218261727812 0 -0.0292979408742882" rpy="0 0 0" />
    <parent link="l1_rf" />
    <child link="l3_rf3" />
    <axis xyz="0 1 0" />
    <limit lower="-1.57" upper="1.57" effort="5" velocity="2" />
  </joint>

  <link name="l4_rf1">
    <inertial>
      <origin xyz="-0.00925877524108323 -0.0350000059049338 -0.0714258099295615" rpy="0 0 0" />
      <mass value="0.505772953738006" />
      <inertia ixx="0.001678" ixy="0.000000" ixz="-0.000035" iyy="0.001703" iyz="0.000000" izz="0.000215" />
    </inertial>
    <visual>
      <origin xyz="0 0 0" rpy="0 0 0" />
      <geometry>
        <mesh filename="package://tryd/meshes/l4_rf1.STL" />
      </geometry>
      <material name="">
        <color rgba="0.898039215686275 0.917647058823529 0.929411764705882 1" />
      </material>
    </visual>
    <collision>
      <origin xyz="0 0 0" rpy="0 0 0" />
      <geometry>
        <mesh filename="package://tryd/meshes/l4_rf1.STL" />
      </geometry>
    </collision>
  </link>
  <joint name="j4_rf1" type="revolute">
    <origin xyz="-0.0833137378878261 0 0.0687227842797317" rpy="0 0 0" />
    <parent link="l2_rf" />
    <child link="l4_rf1" />
    <axis xyz="0 1 0" />
    <limit lower="-1.57" upper="1.57" effort="5" velocity="2" />
  </joint>

  <link name="l4_rf2">
    <inertial>
      <origin xyz="0.0664859496958133 -0.0350000060684984 0.0276945733610566" rpy="0 0 0" />
      <mass value="0.505772947420474" />
      <inertia ixx="0.000611" ixy="0.000000" ixz="0.000651" iyy="0.001703" iyz="0.000000" izz="0.001282" />
    </inertial>
    <visual>
      <origin xyz="0 0 0" rpy="0 0 0" />
      <geometry>
        <mesh filename="package://tryd/meshes/l4_rf2.STL" />
      </geometry>
      <material name="">
        <color rgba="0.898039215686275 0.917647058823529 0.929411764705882 1" />
      </material>
    </visual>
    <collision>
      <origin xyz="0 0 0" rpy="0 0 0" />
      <geometry>
        <mesh filename="package://tryd/meshes/l4_rf2.STL" />
      </geometry>
    </collision>
  </link>
  <joint name="j4_rf2" type="revolute">
    <origin xyz="-0.0178588080611313 0 -0.106513205634962" rpy="0 0 0" />
    <parent link="l2_rf" />
    <child link="l4_rf2" />
    <axis xyz="0 1 0" />
    <limit lower="-1.57" upper="1.57" effort="5" velocity="2" />
  </joint>

  <link name="l4_rf3">
    <inertial>
      <origin xyz="-0.0572271801527385 -0.0350000060490628 0.0437312355375022" rpy="0 0 0" />
      <mass value="0.505772946196365" />
      <inertia ixx="0.000551" ixy="0.000000" ixz="-0.000616" iyy="0.001703" iyz="0.000000" izz="0.001342" />
    </inertial>
    <visual>
      <origin xyz="0 0 0" rpy="0 0 0" />
      <geometry>
        <mesh filename="package://tryd/meshes/l4_rf3.STL" />
      </geometry>
      <material name="">
        <color rgba="0.898039215686275 0.917647058823529 0.929411764705882 1" />
      </material>
    </visual>
    <collision>
      <origin xyz="0 0 0" rpy="0 0 0" />
      <geometry>
        <mesh filename="package://tryd/meshes/l4_rf3.STL" />
      </geometry>
    </collision>
  </link>
  <joint name="j4_rf3" type="revolute">
    <origin xyz="0.101172545948959 0 0.0377904213552305" rpy="0 0 0" />
    <parent link="l2_rf" />
    <child link="l4_rf3" />
    <axis xyz="0 1 0" />
    <limit lower="-1.57" upper="1.57" effort="5" velocity="2" />
  </joint>

  <!-- LTF --> 
  <link name="l2_lf">
    <inertial>
      <origin xyz="-6.09346184621273E-11 0.0291950636027025 2.85822192691364E-10" rpy="0 0 0" />
      <mass value="0.196608558229839" />
      <inertia ixx="0.000799" ixy="0.000000" ixz="0.000000" iyy="0.001288" iyz="0.000000" izz="0.000799" />
    </inertial>
    <visual>
      <origin xyz="0 0 0" rpy="0 0 0" />
      <geometry>
        <mesh filename="package://tryd/meshes/l2_lf.STL" />
      </geometry>
      <material name="">
        <color rgba="0.650980392156863 0.619607843137255 0.588235294117647 1" />
      </material>
    </visual>
    <collision>
      <origin xyz="0 0 0" rpy="0 0 0" />
      <geometry>
        <mesh filename="package://tryd/meshes/l2_lf.STL" />
      </geometry>
    </collision>
  </link>
  <joint name="j2_lf" type="revolute">
    <origin xyz="0.239999999999999 0.128 -0.0100000000000002" rpy="0 0 0" />
    <parent link="base_link" />
    <child link="l2_lf" />
    <axis xyz="0 1 0" />
    <limit lower="-50" upper="50" effort="100" velocity="50" />
  </joint>

  <link name="l1_lf">
    <inertial>
      <origin xyz="-2.22044604925031E-16 0.0161380765502627 -4.56316275036442E-16" rpy="0 0 0" />
      <mass value="0.0354240975198172" />
      <inertia ixx="0.000012" ixy="0.000000" ixz="0.000000" iyy="0.000015" iyz="0.000000" izz="0.000012" />
    </inertial>
    <visual>
      <origin xyz="0 0 0" rpy="0 0 0" />
      <geometry>
        <mesh filename="package://tryd/meshes/l1_lf.STL" />
      </geometry>
      <material name="">
        <color rgba="0.898039215686275 0.917647058823529 0.929411764705882 1" />
      </material>
    </visual>
    <collision>
      <origin xyz="0 0 0" rpy="0 0 0" />
      <geometry>
        <mesh filename="package://tryd/meshes/l1_lf.STL" />
      </geometry>
    </collision>
  </link>
  <joint name="j1_lf" type="revolute">
    <origin xyz="0 0.021 0" rpy="0 0 0" />
    <parent link="l2_lf" />
    <child link="l1_lf" />
    <axis xyz="0 1 0" />
    <limit lower="-1" upper="1" effort="100" velocity="50" />
  </joint>

  <link name="l3_lf1">
    <inertial>
      <origin xyz="-0.039890520885456 0.0139999805842647 0.0482877619143034" rpy="0 0 0" />
      <mass value="0.0557316685279918" />
      <inertia ixx="0.000029" ixy="0.000000" ixz="-0.000032" iyy="0.000071" iyz="0.000000" izz="0.000044" />
    </inertial>
    <visual>
      <origin xyz="0 0 0" rpy="0 0 0" />
      <geometry>
        <mesh filename="package://tryd/meshes/l3_lf1.STL" />
      </geometry>
      <material name="">
        <color rgba="0.898039215686275 0.917647058823529 0.929411764705882 1" />
      </material>
    </visual>
    <collision>
      <origin xyz="0 0 0" rpy="0 0 0" />
      <geometry>
        <mesh filename="package://tryd/meshes/l3_lf1.STL" />
      </geometry>
    </collision>
  </link>
  <joint name="j3_lf1" type="revolute">
    <origin xyz="0.0221395963706941 0 0.0202444627625115" rpy="0 0 0" />
    <parent link="l1_lf" />
    <child link="l3_lf1" />
    <axis xyz="0 1 0" />
    <limit lower="-1.57" upper="1.57" effort="5" velocity="2" />
  </joint>

  <link name="l3_lf2">
    <inertial>
      <origin xyz="-0.0218731667180357 0.0139999963361724 -0.0586901161937509" rpy="0 0 0" />
      <mass value="0.0557315697331413" />
      <inertia ixx="0.000068" ixy="0.000000" ixz="0.000009" iyy="0.000071" iyz="0.000000" izz="0.000006" />
    </inertial>
    <visual>
      <origin xyz="0 0 0" rpy="0 0 0" />
      <geometry>
        <mesh filename="package://tryd/meshes/l3_lf2.STL" />
      </geometry>
      <material name="">
        <color rgba="0.898039215686275 0.917647058823529 0.929411764705882 1" />
      </material>
    </visual>
    <collision>
      <origin xyz="0 0 0" rpy="0 0 0" />
      <geometry>
        <mesh filename="package://tryd/meshes/l3_lf2.STL" />
      </geometry>
    </collision>
  </link>
  <joint name="j3_lf2" type="revolute">
    <origin xyz="-0.0286020172236509 0 0.00905122150529837" rpy="0 0 0" />
    <parent link="l1_lf" />
    <child link="l3_lf2" />
    <axis xyz="0 1 0" />
    <limit lower="-1.57" upper="1.57" effort="5" velocity="2" />
  </joint>

  <link name="l3_lf3">
    <inertial>
      <origin xyz="0.0617637124928111 0.0139999968767433 0.0104023340469134" rpy="0 0 0" />
      <mass value="0.0557315625814885" />
      <inertia ixx="0.000013" ixy="0.000000" ixz="0.000022" iyy="0.000071" iyz="0.000000" izz="0.000061" />
    </inertial>
    <visual>
      <origin xyz="0 0 0" rpy="0 0 0" />
      <geometry>
        <mesh filename="package://tryd/meshes/l3_lf3.STL" />
      </geometry>
      <material name="">
        <color rgba="0.898039215686275 0.917647058823529 0.929411764705882 1" />
      </material>
    </visual>
    <collision>
      <origin xyz="0 0 0" rpy="0 0 0" />
      <geometry>
        <mesh filename="package://tryd/meshes/l3_lf3.STL" />
      </geometry>
    </collision>
  </link>
  <joint name="j3_lf3" type="revolute">
    <origin xyz="0.00646242085295634 0 -0.0292956842678118" rpy="0 0 0" />
    <parent link="l1_lf" />
    <child link="l3_lf3" />
    <axis xyz="0 1 0" />
    <limit lower="-1.57" upper="1.57" effort="5" velocity="2" />
  </joint>

  <link name="l4_lf1">
    <inertial>
      <origin xyz="-0.00923381104475832 0.034999994095162 -0.0714290415484533" rpy="0 0 0" />
      <mass value="0.505772953745336" />
      <inertia ixx="0.001678" ixy="0.000000" ixz="-0.000035" iyy="0.001703" iyz="0.000000" izz="0.000215" />
    </inertial>
    <visual>
      <origin xyz="0 0 0" rpy="0 0 0" />
      <geometry>
        <mesh filename="package://tryd/meshes/l4_lf1.STL" />
      </geometry>
      <material name="">
        <color rgba="0.898039215686275 0.917647058823529 0.929411764705882 1" />
      </material>
    </visual>
    <collision>
      <origin xyz="0 0 0" rpy="0 0 0" />
      <geometry>
        <mesh filename="package://tryd/meshes/l4_lf1.STL" />
      </geometry>
    </collision>
  </link>
  <joint name="j4_lf1" type="revolute">
    <origin xyz="-0.0833137378878259 0 0.068722784279732" rpy="0 0 0" />
    <parent link="l2_lf" />
    <child link="l4_lf1" />
    <axis xyz="0 1 0" />
    <limit lower="-1.57" upper="1.57" effort="5" velocity="2" />
  </joint>
  
  <link name="l4_lf2">
    <inertial>
      <origin xyz="0.0664762662590837 0.0349999939314377 0.0277178088028784" rpy="0 0 0" />
      <mass value="0.505772947416741" />
      <inertia ixx="0.000611" ixy="0.000000" ixz="0.000651" iyy="0.001703" iyz="0.000000" izz="0.001282" />
    </inertial>
    <visual>
      <origin xyz="0 0 0" rpy="0 0 0" />
      <geometry>
        <mesh filename="package://tryd/meshes/l4_lf2.STL" />
      </geometry>
      <material name="">
        <color rgba="0.898039215686275 0.917647058823529 0.929411764705882 1" />
      </material>
    </visual>
    <collision>
      <origin xyz="0 0 0" rpy="0 0 0" />
      <geometry>
        <mesh filename="package://tryd/meshes/l4_lf2.STL" />
      </geometry>
    </collision>
  </link>
  <joint name="j4_lf2" type="revolute">
    <origin xyz="-0.0178588080611317 0 -0.106513205634961" rpy="0 0 0" />
    <parent link="l2_lf" />
    <child link="l4_lf2" />
    <axis xyz="0 1 0" />
    <limit lower="-1.57" upper="1.57" effort="5" velocity="2" />
  </joint>

  <link name="l4_lf3">
    <inertial>
      <origin xyz="-0.0572424609164388 0.0349999939510116 0.0437112317178428" rpy="0 0 0" />
      <mass value="0.505772946198787" />
      <inertia ixx="0.000551" ixy="0.000000" ixz="-0.000616" iyy="0.001703" iyz="0.000000" izz="0.001342" />
    </inertial>
    <visual>
      <origin xyz="0 0 0" rpy="0 0 0" />
      <geometry>
        <mesh filename="package://tryd/meshes/l4_lf3.STL" />
      </geometry>
      <material name="">
        <color rgba="0.898039215686275 0.917647058823529 0.929411764705882 1" />
      </material>
    </visual>
    <collision>
      <origin xyz="0 0 0" rpy="0 0 0" />
      <geometry>
        <mesh filename="package://tryd/meshes/l4_lf3.STL" />
      </geometry>
    </collision>
  </link>
  <joint name="j4_lf3" type="revolute">
    <origin xyz="0.101172545948959 0 0.0377904213552303" rpy="0 0 0" />
    <parent link="l2_lf" />
    <child link="l4_lf3" />
    <axis xyz="0 1 0" />
    <limit lower="-1.57" upper="1.57" effort="5" velocity="2" />
  </joint>

  <!-- RTH --> 
  <link name="l2_rh">
    <inertial>
      <origin xyz="-3.36830535685451E-10 -0.0291950635763487 4.28708644196799E-11" rpy="0 0 0" />
      <mass value="0.196608557895127" />
      <inertia ixx="0.000799" ixy="0.000000" ixz="0.000000" iyy="0.001288" iyz="0.000000" izz="0.000799" />
    </inertial>
    <visual>
      <origin xyz="0 0 0" rpy="0 0 0" />
      <geometry>
        <mesh filename="package://tryd/meshes/l2_rh.STL" />
      </geometry>
      <material name="">
        <color rgba="0.650980392156863 0.619607843137255 0.588235294117647 1" />
      </material>
    </visual>
    <collision>
      <origin xyz="0 0 0" rpy="0 0 0" />
      <geometry>
        <mesh filename="package://tryd/meshes/l2_rh.STL" />
      </geometry>
    </collision>
  </link>
  <joint name="j2_rh" type="revolute">
    <origin xyz="-0.24 -0.128 -0.0100000000000005" rpy="0 0 0" />
    <parent link="base_link" />
    <child link="l2_rh" />
    <axis xyz="0 1 0" />
    <limit lower="-50" upper="50" effort="100" velocity="50" />
  </joint>

  <link name="l1_rh">
    <inertial>
      <origin xyz="3.33066907387547E-16 -0.0161380765502627 -2.59802701229211E-16" rpy="0 0 0" />
      <mass value="0.0354240975198172" />
      <inertia ixx="0.000012" ixy="0.000000" ixz="0.000000" iyy="0.000015" iyz="0.000000" izz="0.000012" />
    </inertial>
    <visual>
      <origin xyz="0 0 0" rpy="0 0 0" />
      <geometry>
        <mesh filename="package://tryd/meshes/l1_rh.STL" />
      </geometry>
      <material name="">
        <color rgba="0.898039215686275 0.917647058823529 0.929411764705882 1" />
      </material>
    </visual>
    <collision>
      <origin xyz="0 0 0" rpy="0 0 0" />
      <geometry>
        <mesh filename="package://tryd/meshes/l1_rh.STL" />
      </geometry>
    </collision>
  </link>
  <joint name="j1_rh" type="revolute">
    <origin xyz="0 -0.021 0" rpy="0 0 0" />
    <parent link="l2_rh" />
    <child link="l1_rh" />
    <axis xyz="0 1 0" />
    <limit lower="-1" upper="1" effort="100" velocity="50" />
  </joint>

  <link name="l3_rh1">
    <inertial>
      <origin xyz="-0.0398905245666619 -0.0140000194157354 0.0482877588732504" rpy="0 0 0" />
      <mass value="0.0557316685279918" />
      <inertia ixx="0.000029" ixy="0.000000" ixz="-0.000032" iyy="0.000071" iyz="0.000000" izz="0.000044" />
    </inertial>
    <visual>
      <origin xyz="0 0 0" rpy="0 0 0" />
      <geometry>
        <mesh filename="package://tryd/meshes/l3_rh1.STL" />
      </geometry>
      <material name="">
        <color rgba="0.898039215686275 0.917647058823529 0.929411764705882 1" />
      </material>
    </visual>
    <collision>
      <origin xyz="0 0 0" rpy="0 0 0" />
      <geometry>
        <mesh filename="package://tryd/meshes/l3_rh1.STL" />
      </geometry>
    </collision>
  </link>
  <joint name="j3_rh1" type="revolute">
    <origin xyz="0.0221466697670692 0 0.0202367244935632" rpy="0 0 0" />
    <parent link="l1_rh" />
    <child link="l3_rh1" />
    <axis xyz="0 1 0" />
    <limit lower="-1.57" upper="1.57" effort="5" velocity="2" />
  </joint>

  <link name="l3_rh2">
    <inertial>
      <origin xyz="-0.0218731622438033 -0.0140000036638276 -0.0586901178612386" rpy="0 0 0" />
      <mass value="0.0557315697331424" />
      <inertia ixx="0.000068" ixy="0.000000" ixz="0.000009" iyy="0.000071" iyz="0.000000" izz="0.000006" />
    </inertial>
    <visual>
      <origin xyz="0 0 0" rpy="0 0 0" />
      <geometry>
        <mesh filename="package://tryd/meshes/l3_rh2.STL" />
      </geometry>
      <material name="">
        <color rgba="0.898039215686275 0.917647058823529 0.929411764705882 1" />
      </material>
    </visual>
    <collision>
      <origin xyz="0 0 0" rpy="0 0 0" />
      <geometry>
        <mesh filename="package://tryd/meshes/l3_rh2.STL" />
      </geometry>
    </collision>
  </link>
  <joint name="j3_rh2" type="revolute">
    <origin xyz="-0.0285988523843469 0 0.00906121638072405" rpy="0 0 0" />
    <parent link="l1_rh" />
    <child link="l3_rh2" />
    <axis xyz="0 1 0" />
    <limit lower="-1.57" upper="1.57" effort="5" velocity="2" />
  </joint>

  <link name="l3_rh3">
    <inertial>
      <origin xyz="0.0617637116997811 -0.0140000031232566 0.0104023387554438" rpy="0 0 0" />
      <mass value="0.0557315625814886" />
      <inertia ixx="0.000013" ixy="0.000000" ixz="0.000022" iyy="0.000071" iyz="0.000000" izz="0.000061" />
    </inertial>
    <visual>
      <origin xyz="0 0 0" rpy="0 0 0" />
      <geometry>
        <mesh filename="package://tryd/meshes/l3_rh3.STL" />
      </geometry>
      <material name="">
        <color rgba="0.898039215686275 0.917647058823529 0.929411764705882 1" />
      </material>
    </visual>
    <collision>
      <origin xyz="0 0 0" rpy="0 0 0" />
      <geometry>
        <mesh filename="package://tryd/meshes/l3_rh3.STL" />
      </geometry>
    </collision>
  </link>
  <joint name="j3_rh3" type="revolute">
    <origin xyz="0.00645218261727887 0 -0.0292979408742888" rpy="0 0 0" />
    <parent link="l1_rh" />
    <child link="l3_rh3" />
    <axis xyz="0 1 0" />
    <limit lower="-1.57" upper="1.57" effort="5" velocity="2" />
  </joint>

  <link name="l4_rh1">
    <inertial>
      <origin xyz="-0.00925877524108371 -0.0350000059049338 -0.0714258099295591" rpy="0 0 0" />
      <mass value="0.505772953738004" />
      <inertia ixx="0.001678" ixy="0.000000" ixz="-0.000035" iyy="0.001703" iyz="0.000000" izz="0.000215" />
    </inertial>
    <visual>
      <origin xyz="0 0 0" rpy="0 0 0" />
      <geometry>
        <mesh filename="package://tryd/meshes/l4_rh1.STL" />
      </geometry>
      <material name="">
        <color rgba="0.898039215686275 0.917647058823529 0.929411764705882 1" />
      </material>
    </visual>
    <collision>
      <origin xyz="0 0 0" rpy="0 0 0" />
      <geometry>
        <mesh filename="package://tryd/meshes/l4_rh1.STL" />
      </geometry>
    </collision>
  </link>
  <joint name="j4_rh1" type="revolute">
    <origin xyz="-0.0833137378878267 0 0.0687227842797326" rpy="0 0 0" />
    <parent link="l2_rh" />
    <child link="l4_rh1" />
    <axis xyz="0 1 0" />
    <limit lower="-1.57" upper="1.57" effort="5" velocity="2" />
  </joint>

  <link name="l4_rh2">
    <inertial>
      <origin xyz="0.0664859496958403 -0.0350000060684984 0.0276945733610724" rpy="0 0 0" />
      <mass value="0.505772947420472" />
      <inertia ixx="0.000611" ixy="0.000000" ixz="0.000651" iyy="0.001703" iyz="0.000000" izz="0.001282" />
    </inertial>
    <visual>
      <origin xyz="0 0 0" rpy="0 0 0" />
      <geometry>
        <mesh filename="package://tryd/meshes/l4_rh2.STL" />
      </geometry>
      <material name="">
        <color rgba="0.898039215686275 0.917647058823529 0.929411764705882 1" />
      </material>
    </visual>
    <collision>
      <origin xyz="0 0 0" rpy="0 0 0" />
      <geometry>
        <mesh filename="package://tryd/meshes/l4_rh2.STL" />
      </geometry>
    </collision>
  </link>
  <joint name="j4_rh2" type="revolute">
    <origin xyz="-0.0178588080611333 0 -0.106513205634961" rpy="0 0 0" />
    <parent link="l2_rh" />
    <child link="l4_rh2" />
    <axis xyz="0 1 0" />
    <limit lower="-1.57" upper="1.57" effort="5" velocity="2" />
  </joint>

  <link name="l4_rh3">
    <inertial>
      <origin xyz="-0.0572271801527114 -0.0350000060490628 0.0437312355374892" rpy="0 0 0" />
      <mass value="0.505772946196363" />
      <inertia ixx="0.000551" ixy="0.000000" ixz="-0.000616" iyy="0.001703" iyz="0.000000" izz="0.001342" />
    </inertial>
    <visual>
      <origin xyz="0 0 0" rpy="0 0 0" />
      <geometry>
        <mesh filename="package://tryd/meshes/l4_rh3.STL" />
      </geometry>
      <material name="">
        <color rgba="0.898039215686275 0.917647058823529 0.929411764705882 1" />
      </material>
    </visual>
    <collision>
      <origin xyz="0 0 0" rpy="0 0 0" />
      <geometry>
        <mesh filename="package://tryd/meshes/l4_rh3.STL" />
      </geometry>
    </collision>
  </link>
  <joint name="j4_rh3" type="revolute">
    <origin xyz="0.101172545948958 0 0.03779042135523" rpy="0 0 0" />
    <parent link="l2_rh" />
    <child link="l4_rh3" />
    <axis xyz="0 1 0" />
    <limit lower="-1.57" upper="1.57" effort="5" velocity="2" />
  </joint>

  <!-- LTH --> 
  <link name="l2_lh">
    <inertial>
      <origin xyz="-6.25409724008819E-11 0.0291950635841788 3.76880211515852E-10" rpy="0 0 0" />
      <mass value="0.196608558024231" />
      <inertia ixx="0.000799" ixy="0.000000" ixz="0.000000" iyy="0.001288" iyz="0.000000" izz="0.000799" />
    </inertial>
    <visual>
      <origin xyz="0 0 0" rpy="0 0 0" />
      <geometry>
        <mesh filename="package://tryd/meshes/l2_lh.STL" />
      </geometry>
      <material name="">
        <color rgba="0.650980392156863 0.619607843137255 0.588235294117647 1" />
      </material>
    </visual>
    <collision>
      <origin xyz="0 0 0" rpy="0 0 0" />
      <geometry>
        <mesh filename="package://tryd/meshes/l2_lh.STL" />
      </geometry>
    </collision>
  </link>
  <joint name="j2_lh" type="revolute">
    <origin xyz="-0.239999999999999 0.128 -0.0100000000000004" rpy="0 0 0" />
    <parent link="base_link" />
    <child link="l2_lh" />
    <axis xyz="0 1 0" />
    <limit lower="-50" upper="50" effort="100" velocity="50" />
  </joint>

  <link name="l1_lh">
    <inertial>
      <origin xyz="4.44089209850063E-16 0.0161380765502627 -4.43160424709541E-17" rpy="0 0 0" />
      <mass value="0.0354240975198174" />
      <inertia ixx="0.000012" ixy="0.000000" ixz="0.000000" iyy="0.000015" iyz="0.000000" izz="0.000012" />
    </inertial>
    <visual>
      <origin xyz="0 0 0" rpy="0 0 0" />
      <geometry>
        <mesh filename="package://tryd/meshes/l1_lh.STL" />
      </geometry>
      <material name="">
        <color rgba="0.898039215686275 0.917647058823529 0.929411764705882 1" />
      </material>
    </visual>
    <collision>
      <origin xyz="0 0 0" rpy="0 0 0" />
      <geometry>
        <mesh filename="package://tryd/meshes/l1_lh.STL" />
      </geometry>
    </collision>
  </link>
  <joint name="j1_lh" type="revolute">
    <origin xyz="0 0.021 0" rpy="0 0 0" />
    <parent link="l2_lh" />
    <child link="l1_lh" />
    <axis xyz="0 1 0" />
    <limit lower="-1" upper="1" effort="100" velocity="50" />
  </joint>

  <link name="l3_lh1">
    <inertial>
      <origin xyz="-0.0398905208854606 0.0139999805842646 0.0482877619143024" rpy="0 0 0" />
      <mass value="0.0557316685279916" />
      <inertia ixx="0.000029" ixy="0.000000" ixz="-0.000032" iyy="0.000071" iyz="0.000000" izz="0.000044" />
    </inertial>
    <visual>
      <origin xyz="0 0 0" rpy="0 0 0" />
      <geometry>
        <mesh filename="package://tryd/meshes/l3_lh1.STL" />
      </geometry>
      <material name="">
        <color rgba="0.898039215686275 0.917647058823529 0.929411764705882 1" />
      </material>
    </visual>
    <collision>
      <origin xyz="0 0 0" rpy="0 0 0" />
      <geometry>
        <mesh filename="package://tryd/meshes/l3_lh1.STL" />
      </geometry>
    </collision>
  </link>
  <joint name="j3_lh3" type="revolute">
    <origin xyz="0.0221395963706951 0 0.0202444627625122" rpy="0 0 0" />
    <parent link="l1_lh" />
    <child link="l3_lh1" />
    <axis xyz="0 1 0" />
    <limit lower="-1.57" upper="1.57" effort="5" velocity="2" />
  </joint>

  <link name="l3_lh2">
    <inertial>
      <origin xyz="-0.0218731667180396 0.0139999963361724 -0.0586901161937471" rpy="0 0 0" />
      <mass value="0.0557315697331413" />
      <inertia ixx="0.000068" ixy="0.000000" ixz="0.000009" iyy="0.000071" iyz="0.000000" izz="0.000006" />
    </inertial>
    <visual>
      <origin xyz="0 0 0" rpy="0 0 0" />
      <geometry>
        <mesh filename="package://tryd/meshes/l3_lh2.STL" />
      </geometry>
      <material name="">
        <color rgba="0.898039215686275 0.917647058823529 0.929411764705882 1" />
      </material>
    </visual>
    <collision>
      <origin xyz="0 0 0" rpy="0 0 0" />
      <geometry>
        <mesh filename="package://tryd/meshes/l3_lh2.STL" />
      </geometry>
    </collision>
  </link>
  <joint name="j3_lh2" type="revolute">
    <origin xyz="-0.02860201722365 0 0.00905122150529934" rpy="0 0 0" />
    <parent link="l1_lh" />
    <child link="l3_lh2" />
    <axis xyz="0 1 0" />
    <limit lower="-1.57" upper="1.57" effort="5" velocity="2" />
  </joint>

  <link name="l3_lh3">
    <inertial>
      <origin xyz="0.0617637124928112 0.0139999968767434 0.0104023340469128" rpy="0 0 0" />
      <mass value="0.0557315625814885" />
      <inertia ixx="0.000013" ixy="0.000000" ixz="0.000022" iyy="0.000071" iyz="0.000000" izz="0.000061" />
    </inertial>
    <visual>
      <origin xyz="0 0 0" rpy="0 0 0" />
      <geometry>
        <mesh filename="package://tryd/meshes/l3_lh3.STL" />
      </geometry>
      <material name="">
        <color rgba="0.898039215686275 0.917647058823529 0.929411764705882 1" />
      </material>
    </visual>
    <collision>
      <origin xyz="0 0 0" rpy="0 0 0" />
      <geometry>
        <mesh filename="package://tryd/meshes/l3_lh3.STL" />
      </geometry>
    </collision>
  </link>
  <joint name="j3_lh1" type="revolute">
    <origin xyz="0.00646242085295679 0 -0.0292956842678109" rpy="0 0 0" />
    <parent link="l1_lh" />
    <child link="l3_lh3" />
    <axis xyz="0 1 0" />
    <limit lower="-1.57" upper="1.57" effort="5" velocity="2" />
  </joint>

  <link name="l4_lh1">
    <inertial>
      <origin xyz="-0.00923381104475846 0.0349999940951619 -0.0714290415484631" rpy="0 0 0" />
      <mass value="0.505772953745337" />
      <inertia ixx="0.001678" ixy="0.000000" ixz="-0.000035" iyy="0.001703" iyz="0.000000" izz="0.000215" />
    </inertial>
    <visual>
      <origin xyz="0 0 0" rpy="0 0 0" />
      <geometry>
        <mesh filename="package://tryd/meshes/l4_lh1.STL" />
      </geometry>
      <material name="">
        <color rgba="0.898039215686275 0.917647058823529 0.929411764705882 1" />
      </material>
    </visual>
    <collision>
      <origin xyz="0 0 0" rpy="0 0 0" />
      <geometry>
        <mesh filename="package://tryd/meshes/l4_lh1.STL" />
      </geometry>
    </collision>
  </link>
  <joint name="j4_lh1" type="revolute">
    <origin xyz="-0.0833137378878265 0 0.0687227842797328" rpy="0 0 0" />
    <parent link="l2_lh" />
    <child link="l4_lh1" />
    <axis xyz="0 1 0" />
    <limit lower="-1.57" upper="1.57" effort="5" velocity="2" />
  </joint>

  <link name="l4_lh2">
    <inertial>
      <origin xyz="0.0664762662590742 0.0349999939314377 0.0277178088028722" rpy="0 0 0" />
      <mass value="0.50577294741674" />
      <inertia ixx="0.000611" ixy="0.000000" ixz="0.000651" iyy="0.001703" iyz="0.000000" izz="0.001282" />
    </inertial>
    <visual>
      <origin xyz="0 0 0" rpy="0 0 0" />
      <geometry>
        <mesh filename="package://tryd/meshes/l4_lh2.STL" />
      </geometry>
      <material name="">
        <color rgba="0.898039215686275 0.917647058823529 0.929411764705882 1" />
      </material>
    </visual>
    <collision>
      <origin xyz="0 0 0" rpy="0 0 0" />
      <geometry>
        <mesh filename="package://tryd/meshes/l4_lh2.STL" />
      </geometry>
    </collision>
  </link>
  <joint name="j4_lh2" type="revolute">
    <origin xyz="-0.0178588080611337 0 -0.106513205634961" rpy="0 0 0" />
    <parent link="l2_lh" />
    <child link="l4_lh2" />
    <axis xyz="0 1 0" />
    <limit lower="-1.57" upper="1.57" effort="5" velocity="2" />
  </joint>

  <link name="l4_lh3">
    <inertial>
      <origin xyz="-0.0572424609164394 0.0349999939510118 0.0437112317178444" rpy="0 0 0" />
      <mass value="0.505772946198786" />
      <inertia ixx="0.000551" ixy="0.000000" ixz="-0.000616" iyy="0.001703" iyz="0.000000" izz="0.001342" />
    </inertial>
    <visual>
      <origin xyz="0 0 0" rpy="0 0 0" />
      <geometry>
        <mesh filename="package://tryd/meshes/l4_lh3.STL" />
      </geometry>
      <material name="">
        <color rgba="0.898039215686275 0.917647058823529 0.929411764705882 1" />
      </material>
    </visual>
    <collision>
      <origin xyz="0 0 0" rpy="0 0 0" />
      <geometry>
        <mesh filename="package://tryd/meshes/l4_lh3.STL" />
      </geometry>
    </collision>
  </link>
  <joint name="j4_lh3" type="revolute">
    <origin xyz="0.101172545948959 0 0.0377904213552296" rpy="0 0 0" />
    <parent link="l2_lh" />
    <child link="l4_lh3" />
    <axis xyz="0 1 0" />
    <limit lower="-1.57" upper="1.57" effort="5" velocity="2" />
  </joint>
  <!-- <joint name='j41_jh3' type='revolute'>
    <origin xyz="0.100052545948959 0 0.0504213552296" rpy="0 0 0" />
    <parent link="l3_lh3" />
    <child link="l4_lh3" />
    <axis xyz="0 1 0" />
    <limit lower="-1.57" upper="1.57" effort="5" velocity="2" />
  </joint> -->
  <!-- Pegasus gazebo plugin -->



  <!-- rtf -->
  <gazebo reference="l4_rf1">
    <mu1>0.6</mu1>
    <mu2>0.6</mu2>
    <self_collide>1</self_collide>
    <material>Gazebo/White</material>
    <kp value="1000000"/>
    <kd value="10.0"/>
  </gazebo>
  <gazebo reference="l4_rf2">
    <mu1>0.6</mu1>
    <mu2>0.6</mu2>
    <self_collide>1</self_collide>
    <material>Gazebo/White</material>
    <kp value="1000000"/>
    <kd value="10.0"/>
  </gazebo>
  <gazebo reference="l4_rf3">
    <mu1>0.6</mu1>
    <mu2>0.6</mu2>
    <self_collide>1</self_collide>
    <material>Gazebo/White</material>
    <kp value="1000000"/>
    <kd value="10.0"/>
  </gazebo>
  <gazebo reference="l3_rf1">
    <mu1>0.1</mu1>
    <mu2>0.1</mu2>
    <self_collide>1</self_collide>
    <material>Gazebo/Grey</material>
  </gazebo>
  <gazebo reference="l3_rf2">
    <mu1>0.1</mu1>
    <mu2>0.1</mu2>
    <self_collide>1</self_collide>
    <material>Gazebo/Grey</material>
  </gazebo>
  <gazebo reference="l3_rf3">
    <mu1>0.1</mu1>
    <mu2>0.1</mu2>
    <self_collide>1</self_collide>
    <material>Gazebo/Grey</material>
  </gazebo> 
  <gazebo reference="l2_rf">
    <mu1>0.6</mu1>
    <mu2>0.6</mu2>
    <self_collide>1</self_collide>
    <material>Gazebo/White</material>
    <kp value="1000000"/>
    <kd value="10.0"/>
  </gazebo>
  <gazebo reference="l1_rf">
    <mu1>0.1</mu1>
    <mu2>0.1</mu2>
    <self_collide>1</self_collide>
    <material>Gazebo/Grey</material>
  </gazebo>

  <!-- ltf -->
  <gazebo reference="l4_lf1">
    <mu1>0.6</mu1>
    <mu2>0.6</mu2>
    <self_collide>1</self_collide>
    <material>Gazebo/White</material>
    <kp value="1000000"/>
    <kd value="10.0"/>
  </gazebo>
  <gazebo reference="l4_lf2">
    <mu1>0.6</mu1>
    <mu2>0.6</mu2>
    <self_collide>1</self_collide>
    <material>Gazebo/White</material>
    <kp value="1000000"/>
    <kd value="10.0"/>
  </gazebo>
  <gazebo reference="l4_lf3">
    <mu1>0.6</mu1>
    <mu2>0.6</mu2>
    <self_collide>1</self_collide>
    <material>Gazebo/White</material>
    <kp value="1000000"/>
    <kd value="10.0"/>
  </gazebo>
  <gazebo reference="l3_lf1">
    <mu1>0.1</mu1>
    <mu2>0.1</mu2>
    <self_collide>1</self_collide>
    <material>Gazebo/Grey</material>
  </gazebo>
  <gazebo reference="l3_lf2">
    <mu1>0.1</mu1>
    <mu2>0.1</mu2>
    <self_collide>1</self_collide>
    <material>Gazebo/Grey</material>
  </gazebo>
  <gazebo reference="l3_lf3">
    <mu1>0.1</mu1>
    <mu2>0.1</mu2>
    <self_collide>1</self_collide>
    <material>Gazebo/Grey</material>
  </gazebo>
  <gazebo reference="l2_lf">
    <mu1>0.6</mu1>
    <mu2>0.6</mu2>
    <self_collide>1</self_collide>
    <material>Gazebo/White</material>
    <kp value="1000000"/>
    <kd value="10.0"/>  
  </gazebo>
  <gazebo reference="l1_lf">
    <mu1>0.1</mu1>
    <mu2>0.1</mu2>
    <self_collide>1</self_collide>
    <material>Gazebo/Grey</material>
  </gazebo>

  <!-- rth -->
  <gazebo reference="l4_rh1">
    <mu1>0.6</mu1>
    <mu2>0.6</mu2>
    <self_collide>1</self_collide>
    <material>Gazebo/White</material>
    <kp value="1000000"/>
    <kd value="10.0"/>
  </gazebo>
  <gazebo reference="l4_rh2">
    <mu1>0.6</mu1>
    <mu2>0.6</mu2>
    <self_collide>1</self_collide>
    <material>Gazebo/White</material>
    <kp value="1000000"/>
    <kd value="10.0"/>
  </gazebo>
  <gazebo reference="l4_rh3">
    <mu1>0.6</mu1>
    <mu2>0.6</mu2>
    <self_collide>1</self_collide>
    <material>Gazebo/White</material>
    <kp value="1000000"/>
    <kd value="10.0"/>
  </gazebo>
  <gazebo reference="l3_rh1">
    <mu1>0.1</mu1>
    <mu2>0.1</mu2>
    <self_collide>1</self_collide>
    <material>Gazebo/Grey</material>
  </gazebo>
  <gazebo reference="l3_rh2">
    <mu1>0.1</mu1>
    <mu2>0.1</mu2>
    <self_collide>1</self_collide>
    <material>Gazebo/Grey</material>
  </gazebo>
  <gazebo reference="l3_rh3">
    <mu1>0.1</mu1>
    <mu2>0.1</mu2>
    <self_collide>1</self_collide>
    <material>Gazebo/Grey</material> 
  </gazebo>
  <gazebo reference="l2_rh">
    <mu1>0.6</mu1>
    <mu2>0.6</mu2>
    <self_collide>1</self_collide>
    <material>Gazebo/White</material>
    <kp value="1000000"/>
    <kd value="10.0"/>                
  </gazebo>
  <gazebo reference="l1_rh">
    <mu1>0.1</mu1>
    <mu2>0.1</mu2>
    <self_collide>1</self_collide>
    <material>Gazebo/Grey</material>
  </gazebo>

  <!-- lth -->
  <gazebo reference="l4_lh1">
    <mu1>0.6</mu1>
    <mu2>0.6</mu2>
    <self_collide>1</self_collide>
    <material>Gazebo/White</material>
    <kp value="1000000"/>
    <kd value="10.0"/>
  </gazebo>
  <gazebo reference="l4_lh2">
    <mu1>0.6</mu1>
    <mu2>0.6</mu2>
    <self_collide>1</self_collide>
    <material>Gazebo/White</material>
    <kp value="1000000"/>
    <kd value="10.0"/>
  </gazebo>
  <gazebo reference="l4_lh3">
    <mu1>0.6</mu1>
    <mu2>0.6</mu2>
    <self_collide>1</self_collide>
    <material>Gazebo/White</material>
    <kp value="1000000"/>
    <kd value="10.0"/>
  </gazebo>
  <gazebo reference="l3_lh1">
    <mu1>0.1</mu1>
    <mu2>0.1</mu2>
    <self_collide>1</self_collide>
    <material>Gazebo/Grey</material>
  </gazebo>
  <gazebo reference="l3_lh2">
    <mu1>0.1</mu1>
    <mu2>0.1</mu2>
    <self_collide>1</self_collide>
    <material>Gazebo/Grey</material>
  </gazebo>
  <gazebo reference="l3_lh3">
    <mu1>0.1</mu1>
    <mu2>0.1</mu2>
    <self_collide>1</self_collide>
    <material>Gazebo/Grey</material>
  </gazebo>
  <gazebo reference="l2_lh">
    <mu1>0.6</mu1>
    <mu2>0.6</mu2>
    <self_collide>1</self_collide>
    <material>Gazebo/White</material>
    <kp value="1000000"/>
    <kd value="10.0"/>
  </gazebo>
  <gazebo reference="l1_lh">
    <mu1>0.1</mu1>
    <mu2>0.1</mu2>
    <self_collide>1</self_collide>
    <material>Gazebo/Grey</material>
  </gazebo> 
  
  <!-- IMU -->
  <joint name="imu_joint" type="fixed">
    <parent link="base_link"/>
    <child link="imu_link"/>
    <origin rpy="0 0 0" xyz="0 0 0"/>
  </joint>

  <link name="imu_link">
    <inertial>
      <mass value="0.001"/>
      <origin rpy="0 0 0" xyz="0 0 0"/>
      <inertia ixx="0.0001" ixy="0" ixz="0" iyy="0.0001" iyz="0" izz="0.0001"/>
    </inertial>
    <visual>
      <origin rpy="0 0 0" xyz="0 0 0"/>
      <geometry>
        <box size="0.001 0.001 0.001"/>
      </geometry>
      <material name=""/>
    </visual>
    <collision>
      <origin rpy="0 0 0" xyz="0 0 0"/>
      <geometry>
        <box size="0.001 0.001 0.001"/>
      </geometry>
    </collision>
  </link>
  
  <!-- imu sensor -->
  <gazebo reference="imu_link">
    <sensor name="imu" type="imu">
      <always_on>1</always_on>
      <update_rate>200</update_rate>
      <visualize>true</visualize>
      <topic>imu</topic>
      <enable_metrics>true</enable_metrics>
      <gz_frame_id>imu_link</gz_frame_id>
    </sensor>
  </gazebo>
<!-- <gazebo>
  <plugin name="differential_drive_controller" filename="libgazebo_ros_diff_drive.so">
    <updateRate> 50 </updateRate>
  
    <rightJoint>l2_lf</rightJoint>
    <leftJoint>l2_lf</leftJoint>
   


    <wheelSeparation>0.256</wheelSeparation>
    <wheelDiameter>0.118</wheelDiameter>
    <wheelAcceleration>1.0</wheelAcceleration>
    <wheelTorque>20</wheelTorque>
    <commandTopic>cmd_vel</commandTopic>
    <odometryTopic>odom</odometryTopic>
    <odometryFrame>odom</odometryFrame>
    <robotBaseFrame>base_footprint</robotBaseFrame>
    <odometrySource>1</odometrySource>
    <publishWheelTF>true</publishWheelTF>
    <publishOdom>true</publishOdom>
    <publishWheelJointState>true</publishWheelJointState>
    <legacyMode>false</legacyMode>
  </plugin>
</gazebo> -->

</robot>